Workbook
Name Consulta2: Ponderación!$A$1:$B$48

Sheet Hoja1
A1: CONSOLIDADO | B1: DESCRIPCION CODIGOS DE CUATRO CARACTERES | C1: COD 3 | D1: DESCRIPCION CODIGOS DE TRES CARACTERES | E1: CATEGORIA | F1: GRUPO DE RIESGO | G1: SUBGRUPO_RIESGO | H1: Nivel.Riesgo | I1: NOMBRE_DX | J1: POBLACION PRINCIPAL | K1: Seguimiento Programa | L1: Cohorte/APS | M1: CIE10_INCLUIDO= 1/ CIE_10_EXCLUIDO = 2 | N1: Temporalidad para retiro de la cohorte
A2: X600 | B2: ENVENENAMIENTO AUTOINFLIGIDO INTENCIONALMENTE POR, Y EXPOSICION A ANALGESICOS NO NARCOTICOS, ANTIPIRETICOS Y ANTIRREUMATICOS: VIVIENDA | C2: X60 | D2: ENVENENAMIENTO AUTOINFLINGIDO INTENCIONALMENTE POR, Y EXPOSICION A ANALGESICOS NO NARCOTICOS, ANTIPIRETICOS Y ANTIRREUMATICOS | E2: LESIONES AUTOINFLIGIDAS INTENCIONALMENTE (X60–X84) | F2: 2 | G2: 2 | H2: 22 | I2: Tentativa o intento de suicidio | J2: Ambas | K2: En Programa | L2: APS | N2: 6 meses
A3: X601 | B3: ENVENENAMIENTO AUTOINFLIGIDO INTENCIONALMENTE POR, Y EXPOSICION A ANALGESICOS NO NARCOTICOS, ANTIPIRETICOS Y ANTIRREUMATICOS: INSTITUCION RESIDENCIAL | C3: X60 | D3: ENVENENAMIENTO AUTOINFLINGIDO INTENCIONALMENTE POR, Y EXPOSICION A ANALGESICOS NO NARCOTICOS, ANTIPIRETICOS Y ANTIRREUMATICOS | E3: LESIONES AUTOINFLIGIDAS INTENCIONALMENTE (X60–X84) | F3: 2 | G3: 2 | H3: 22 | I3: Tentativa o intento de suicidio | J3: Ambas | K3: En Programa | L3: APS | N3: 6 meses
A4: X602 | B4: ENVENENAMIENTO AUTOINFLIGIDO INTENCIONALMENTE POR, Y EXPOSICION A ANALGESICOS NO NARCOTICOS, ANTIPIRETICOS Y ANTIRREUMATICOS: ESCUELAS, OTRAS INSTITUCIONES Y AREAS ADMINISTRATIVAS PUBLICAS | C4: X60 | D4: ENVENENAMIENTO AUTOINFLINGIDO INTENCIONALMENTE POR, Y EXPOSICION A ANALGESICOS NO NARCOTICOS, ANTIPIRETICOS Y ANTIRREUMATICOS | E4: LESIONES AUTOINFLIGIDAS INTENCIONALMENTE (X60–X84) | F4: 2 | G4: 2 | H4: 22 | I4: Tentativa o intento de suicidio | J4: Ambas | K4: En Programa | L4: APS | N4: Sin segmentación
A5: X603 | B5: ENVENENAMIENTO AUTOINFLIGIDO INTENCIONALMENTE POR, Y EXPOSICION A ANALGESICOS NO NARCOTICOS, ANTIPIRETICOS Y ANTIRREUMATICOS: AREAS DE DEPORTE Y ATLETISMO | C5: X60 | D5: ENVENENAMIENTO AUTOINFLINGIDO INTENCIONALMENTE POR, Y EXPOSICION A ANALGESICOS NO NARCOTICOS, ANTIPIRETICOS Y ANTIRREUMATICOS | E5: LESIONES AUTOINFLIGIDAS INTENCIONALMENTE (X60–X84) | F5: 2 | G5: 2 | H5: 22 | I5: Tentativa o intento de suicidio | J5: Ambas | K5: En Programa | L5: APS | N5: Sin segmentación
A6: X604 | B6: ENVENENAMIENTO AUTOINFLIGIDO INTENCIONALMENTE POR, Y EXPOSICION A ANALGESICOS NO NARCOTICOS, ANTIPIRETICOS Y ANTIRREUMATICOS: CALLES Y CARRETERAS | C6: X60 | D6: ENVENENAMIENTO AUTOINFLINGIDO INTENCIONALMENTE POR, Y EXPOSICION A ANALGESICOS NO NARCOTICOS, ANTIPIRETICOS Y ANTIRREUMATICOS | E6: LESIONES AUTOINFLIGIDAS INTENCIONALMENTE (X60–X84) | F6: 2 | G6: 2 | H6: 22 | I6: Tentativa o intento de suicidio | J6: Ambas | K6: En Programa | L6: APS | N6: 6 meses
A7: X605 | B7: ENVENENAMIENTO AUTOINFLIGIDO INTENCIONALMENTE POR, Y EXPOSICION A ANALGESICOS NO NARCOTICOS, ANTIPIRETICOS Y ANTIRREUMATICOS: COMERCIO Y AREAS DE SERVICIO | C7: X60 | D7: ENVENENAMIENTO AUTOINFLINGIDO INTENCIONALMENTE POR, Y EXPOSICION A ANALGESICOS NO NARCOTICOS, ANTIPIRETICOS Y ANTIRREUMATICOS | E7: LESIONES AUTOINFLIGIDAS INTENCIONALMENTE (X60–X84) | F7: 2 | G7: 2 | H7: 22 | I7: Tentativa o intento de suicidio | J7: Ambas | K7: En Programa | L7: APS | N7: Sin segmentación
A8: X606 | B8: ENVENENAMIENTO AUTOINFLIGIDO INTENCIONALMENTE POR, Y EXPOSICION A ANALGESICOS NO NARCOTICOS, ANTIPIRETICOS Y ANTIRREUMATICOS: AREA INDUSTRIAL Y DE LA CONSTRUCCION | C8: X60 | D8: ENVENENAMIENTO AUTOINFLINGIDO INTENCIONALMENTE POR, Y EXPOSICION A ANALGESICOS NO NARCOTICOS, ANTIPIRETICOS Y ANTIRREUMATICOS | E8: LESIONES AUTOINFLIGIDAS INTENCIONALMENTE (X60–X84) | F8: 2 | G8: 2 | H8: 22 | I8: Tentativa o intento de suicidio | J8: Ambas | K8: En Programa | L8: APS | N8: 6 meses
A9: X607 | B9: ENVENENAMIENTO AUTOINFLIGIDO INTENCIONALMENTE POR, Y EXPOSICION A ANALGESICOS NO NARCOTICOS, ANTIPIRETICOS Y ANTIRREUMATICOS: GRANJA | C9: X60 | D9: ENVENENAMIENTO AUTOINFLINGIDO INTENCIONALMENTE POR, Y EXPOSICION A ANALGESICOS NO NARCOTICOS, ANTIPIRETICOS Y ANTIRREUMATICOS | E9: LESIONES AUTOINFLIGIDAS INTENCIONALMENTE (X60–X84) | F9: 2 | G9: 2 | H9: 22 | I9: Tentativa o intento de suicidio | J9: Ambas | K9: En Programa | L9: APS | N9: Sin segmentación
A10: X608 | B10: ENVENENAMIENTO AUTOINFLIGIDO INTENCIONALMENTE POR, Y EXPOSICION A ANALGESICOS NO NARCOTICOS, ANTIPIRETICOS Y ANTIRREUMATICOS: OTRO LUGAR ESPECIFICADO | C10: X60 | D10: ENVENENAMIENTO AUTOINFLINGIDO INTENCIONALMENTE POR, Y EXPOSICION A ANALGESICOS NO NARCOTICOS, ANTIPIRETICOS Y ANTIRREUMATICOS | E10: LESIONES AUTOINFLIGIDAS INTENCIONALMENTE (X60–X84) | F10: 2 | G10: 2 | H10: 22 | I10: Tentativa o intento de suicidio | J10: Ambas | K10: En Programa | L10: APS | N10: Sin segmentación
A11: X609 | B11: ENVENENAMIENTO AUTOINFLIGIDO INTENCIONALMENTE POR, Y EXPOSICION A ANALGESICOS NO NARCOTICOS, ANTIPIRETICOS Y ANTIRREUMATICOS: LUGAR NO ESPECIFICADO | C11: X60 | D11: ENVENENAMIENTO AUTOINFLINGIDO INTENCIONALMENTE POR, Y EXPOSICION A ANALGESICOS NO NARCOTICOS, ANTIPIRETICOS Y ANTIRREUMATICOS | E11: LESIONES AUTOINFLIGIDAS INTENCIONALMENTE (X60–X84) | F11: 2 | G11: 2 | H11: 22 | I11: Tentativa o intento de suicidio | J11: Ambas | K11: En Programa | L11: APS | N11: 6 meses
A12: X610 | B12: ENVENENAMIENTO AUTOINFLIGIDO INTENCIONALMENTE POR, Y EXPOSICION A DROGAS ANTIEPILEPTICAS, SEDANTES, HIPNOTICAS, ANTIPARKINSONIANAS Y PSICOTROPICAS, NO CLASIFICADAS EN OTRA PARTE: VIVIENDA | C12: X61 | D12: ENVENENAMIENTO AUTOINFLINGIDO INTENCIONALMENTE POR, Y EXPOSICION A DROGAS ANTIEPILEPTICAS, SEDANTES, HIPNOTICAS, ANTIPARINSONIANAS Y PSICOTROPICAS, NO CLASIFICADAS EN OTRA PARTE | E12: LESIONES AUTOINFLIGIDAS INTENCIONALMENTE (X60–X84) | F12: 2 | G12: 2 | H12: 22 | I12: Tentativa o intento de suicidio | J12: Ambas | K12: En Programa | L12: APS | N12: 6 meses
A13: X611 | B13: ENVENENAMIENTO AUTOINFLIGIDO INTENCIONALMENTE POR, Y EXPOSICION A DROGAS ANTIEPILEPTICAS, SEDANTES, HIPNOTICAS, ANTIPARKINSONIANAS Y PSICOTROPICAS, NO CLASIFICADAS EN OTRA PARTE: INSTITUCION RESIDENCIAL | C13: X61 | D13: ENVENENAMIENTO AUTOINFLINGIDO INTENCIONALMENTE POR, Y EXPOSICION A DROGAS ANTIEPILEPTICAS, SEDANTES, HIPNOTICAS, ANTIPARINSONIANAS Y PSICOTROPICAS, NO CLASIFICADAS EN OTRA PARTE | E13: LESIONES AUTOINFLIGIDAS INTENCIONALMENTE (X60–X84) | F13: 2 | G13: 2 | H13: 22 | I13: Tentativa o intento de suicidio | J13: Ambas | K13: En Programa | L13: APS | N13: 6 meses
... A880: F98 | B880: ENURESIS NO ORGANICA | C880: F98 | D880: OTROS TRASTORNOS EMOCIONALES Y DEL COMPORTAMIENTO QUE APARECEN HABITUALMENTE EN LA NINEZ Y EN LA ADOLESCENCIA | E880: TX. EMOCIONALES Y DEL COMPORTAMIENTO EN LA NIÑEZ Y LA ADOLESCENCIA (F90–F98) | F880: 3 | G880: 1 | H880: 31 | I880: Trastornos Emocionales y Comportamentales | J880: Niños | K880: Fuera Programa | L880: Programa | N880: 6 meses

Sheet Consolidado Paramétrica
A1: CONSOLIDADO | B1: Cie10_4DIGITOS DESCRIPCION | C1: DX_CIE3_DIGITOS | D1: DX_CIE3_DESCRIPCION | E1: AGRUPADOR | F1: PONDERACION | G1: COHORTE | H1: SUBCOHORTE | I1: G_SG_RIESGO | J1: G_SG_RIESGO | K1: RETIRO | L1: POBLACION PRINCIPAL | M1: Seguimiento Programa | N1: Cohorte/APS | O1: CIE10_INCLUIDO= 1/ CIE_10_EXCLUIDO = 2 | P1: NOMBRE_DX
A2: F00 | B2: DEMENCIA EN LA ENFERMEDAD DE ALZHEIMER | C2: F00 | D2: DEMENCIA EN LA ENFERMEDAD DE ALZHEIMER | E2: DEMENCIA | F2: 39 | G2: TRASTORNO COGNOSCITIVO | H2: TRASTORNO COGNOSCITIVO MAYOR | I2: 4.2 | J2: 42 | K2: Nunca | L2: ADULTOS | M2: Fuera Programa | N2: Programa | P2: Demencia
A3: F000 | B3: DEMENCIA EN LA ENFERMEDAD DE ALZHEIMER, DE COMIENZO TEMPRANO (G30.0†) | C3: F00 | D3: DEMENCIA EN LA ENFERMEDAD DE ALZHEIMER | E3: DEMENCIA | F3: 39 | G3: TRASTORNO COGNOSCITIVO | H3: TRASTORNO COGNOSCITIVO MAYOR | I3: 4.2 | J3: 42 | K3: Nunca | L3: ADULTOS | M3: En Programa | N3: Programa | P3: Demencia
A4: F001 | B4: DEMENCIA EN LA ENFERMEDAD DE ALZHEIMER, DE COMIENZO TARDIO (G30.1†) | C4: F00 | D4: DEMENCIA EN LA ENFERMEDAD DE ALZHEIMER | E4: DEMENCIA | F4: 39 | G4: TRASTORNO COGNOSCITIVO | H4: TRASTORNO COGNOSCITIVO MAYOR | I4: 4.2 | J4: 42 | K4: Nunca | L4: ADULTOS | M4: En Programa | N4: Programa | P4: Demencia
A5: F002 | B5: DEMENCIA EN LA ENFERMEDAD DE ALZHEIMER, ATIPICA O DE TIPO MIXTO (G30.8†) | C5: F00 | D5: DEMENCIA EN LA ENFERMEDAD DE ALZHEIMER | E5: DEMENCIA | F5: 39 | G5: TRASTORNO COGNOSCITIVO | H5: TRASTORNO COGNOSCITIVO MAYOR | I5: 4.2 | J5: 42 | K5: Nunca | L5: ADULTOS | M5: En Programa | N5: Programa | P5: Demencia
A6: F009 | B6: DEMENCIA EN LA ENFERMEDAD DE ALZHEIMER, NO ESPECIFICADA (G30.9†) | C6: F00 | D6: DEMENCIA EN LA ENFERMEDAD DE ALZHEIMER | E6: DEMENCIA | F6: 39 | G6: TRASTORNO COGNOSCITIVO | H6: TRASTORNO COGNOSCITIVO MAYOR | I6: 4.2 | J6: 42 | K6: Nunca | L6: ADULTOS | M6: En Programa | N6: Programa | P6: Demencia
A7: F01 | B7: DEMENCIA VASCULAR | C7: F01 | D7: DEMENCIA VASCULAR | E7: DEMENCIA | F7: 39 | G7: TRASTORNO COGNOSCITIVO | H7: TRASTORNO COGNOSCITIVO MAYOR | I7: 4.2 | J7: 42 | K7: Nunca | L7: ADULTOS | M7: Fuera Programa | N7: Programa | P7: Demencia
A8: F010 | B8: DEMENCIA VASCULAR DE COMIENZO AGUDO | C8: F01 | D8: DEMENCIA VASCULAR | E8: DEMENCIA | F8: 39 | G8: TRASTORNO COGNOSCITIVO | H8: TRASTORNO COGNOSCITIVO MAYOR | I8: 4.2 | J8: 42 | K8: Nunca | L8: ADULTOS | M8: En Programa | N8: Programa | P8: Demencia
A9: F011 | B9: DEMENCIA VASCULAR POR INFARTOS MULTIPLES | C9: F01 | D9: DEMENCIA VASCULAR | E9: DEMENCIA | F9: 39 | G9: TRASTORNO COGNOSCITIVO | H9: TRASTORNO COGNOSCITIVO MAYOR | I9: 4.2 | J9: 42 | K9: Nunca | L9: ADULTOS | M9: En Programa | N9: Programa | P9: Demencia
A10: F012 | B10: DEMENCIA VASCULAR SUBCORTICAL | C10: F01 | D10: DEMENCIA VASCULAR | E10: DEMENCIA | F10: 39 | G10: TRASTORNO COGNOSCITIVO | H10: TRASTORNO COGNOSCITIVO MAYOR | I10: 4.2 | J10: 42 | K10: Nunca | L10: ADULTOS | M10: En Programa | N10: Programa | P10: Demencia
A11: F013 | B11: DEMENCIA VASCULAR MIXTA, CORTICAL Y SUBCORTICAL | C11: F01 | D11: DEMENCIA VASCULAR | E11: DEMENCIA | F11: 39 | G11: TRASTORNO COGNOSCITIVO | H11: TRASTORNO COGNOSCITIVO MAYOR | I11: 4.2 | J11: 42 | K11: Nunca | L11: ADULTOS | M11: En Programa | N11: Programa | P11: Demencia
A12: F018 | B12: OTRAS DEMENCIAS VASCULARES | C12: F01 | D12: DEMENCIA VASCULAR | E12: DEMENCIA | F12: 39 | G12: TRASTORNO COGNOSCITIVO | H12: TRASTORNO COGNOSCITIVO MAYOR | I12: 4.2 | J12: 42 | K12: Nunca | L12: ADULTOS | M12: En Programa | N12: Programa | P12: Demencia
A13: F019 | B13: DEMENCIA VASCULAR, NO ESPECIFICADA | C13: F01 | D13: DEMENCIA VASCULAR | E13: DEMENCIA | F13: 39 | G13: TRASTORNO COGNOSCITIVO | H13: TRASTORNO COGNOSCITIVO MAYOR | I13: 4.2 | J13: 42 | K13: Nunca | L13: ADULTOS | M13: En Programa | N13: Programa | P13: Demencia
... A939: Y870 | B939: SECUELAS DE LESIONES AUTOINFLIGIDAS | C939: Y87 | D939: SECUELAS DE LESIONES AUTOINFLIGIDAS INTENCIONALMENTE, AGRESIONES Y EVENTOS DE INTENCION NO DETERMINADA | E939: FACTORES PSICOLOGICOS Y DEL COMPORTAMIENTO ASOCIADOS CON TRASTORNOS O ENFERMEDADES CLASIFICADOS EN OTRA PARTE | F939: 4 | G939: FACTORES DE RIESGO EN SALUD MENTAL | H939: FACTORES DE RIESGO | I939: 1.1 | J939: 11 | K939: Nunca | L939: AMBAS | M939: En Programa | N939: APS | P939: Tentativa o intento de suicidio

Sheet Hoja3
A1: AGRUPADOR | B1: COHORTE | C1: G_SG_RIESGO | D1: NOMBRE_DX
A2: DEMENCIA | B2: TRASTORNO COGNOSCITIVO | C2: 42 | D2: Demencia
A3: EPISODIO DEPRESIVO | B3: EPISODIOS DEPRESIVOS Y TRANSTORNOS DEPRESIVOS | C3: 41 | D3: Episodio Depresivo
A4: EPISODIO DEPRESIVO | B4: EPISODIOS DEPRESIVOS Y TRANSTORNOS DEPRESIVOS | C4: 42 | D4: Episodio Depresivo
A5: ESQUIZOFRENIA | B5: ESQUIZOFRENIA Y AFINES | C5: 42 | D5: Esquizofrenia y afines
A6: DEPRESION | B6: ESQUIZOFRENIA Y AFINES | C6: 42 | D6: Esquizofrenia y afines
A7: TRASTORNO ESQUIZOTIPICO | B7: ESQUIZOFRENIA Y AFINES | C7: 42 | D7: Esquizofrenia y afines
A8: TRASTORNOS DELIRANTES PERSISTENTES | B8: ESQUIZOFRENIA Y AFINES | C8: 42 | D8: Esquizofrenia y afines
A9: TRASTORNOS PSICOTICOS AGUDOS Y TRANSITORIOS | B9: ESQUIZOFRENIA Y AFINES | C9: 42 | D9: Esquizofrenia y afines
A10: TRASTORNO DELIRANTE INDUCIDO | B10: ESQUIZOFRENIA Y AFINES | C10: 42 | D10: Esquizofrenia y afines
A11: TRASTORNOS ESQUIZOAFECTIVO | B11: ESQUIZOFRENIA Y AFINES | C11: 42 | D11: Esquizofrenia y afines
A12: OTROS TRASTORNOS PSICOTICOS DE ORIGEN NO ORGANICO | B12: ESQUIZOFRENIA Y AFINES | C12: 42 | D12: Esquizofrenia y afines
... A79: TRASTORNOS GENERALIZADOS DEL DESARROLLO | B79: TRASTORNOS DEL DESARROLLO | C79: 42 | D79: Trastornos Generalizados del Desarrollo

Sheet Validacion EPS-Keralty
A1: DEFINICIÓN | B1: CONSOLIDADO | C1: DESCRIPCION CODIGOS DE CUATRO CARACTERES | D1: COD 3 | E1: DESCRIPCION CODIGOS DE TRES CARACTERES | F1: CATEGORIA | G1: GRUPO DE RIESGO | H1: SUBGRUPO_RIESGO | I1: Nivel.Riesgo | J1: NOMBRE_DX | K1: POBLACION PRINCIPAL | L1: Seguimiento Programa | M1: Cohorte/APS | N1: Temporalidad para retiro de la cohorte | O1: Nombre grupo en KERALTY | P1: CRUCE PARAMÉTRICA KERALTY COD 4 DIGITOS | Q1: CRUCE PARAMETRICA KERALTY COD 3 DIGITOS
B2: X600 | C2: ENVENENAMIENTO AUTOINFLIGIDO INTENCIONALMENTE POR, Y EXPOSICION A ANALGESICOS NO NARCOTICOS, ANTIPIRETICOS Y ANTIRREUMATICOS: VIVIENDA | D2: X60 | E2: ENVENENAMIENTO AUTOINFLINGIDO INTENCIONALMENTE POR, Y EXPOSICION A ANALGESICOS NO NARCOTICOS, ANTIPIRETICOS Y ANTIRREUMATICOS | F2: LESIONES AUTOINFLIGIDAS INTENCIONALMENTE (X60–X84) | G2: 2 | H2: 2 | I2: 22 | J2: Tentativa o intento de suicidio | K2: Ambas | L2: En Programa | M2: APS | N2: 6 meses | O2: LESIONES AUTOINFLINGUIDAS Y SECUELAS | P2: =VLOOKUP(B2,'Validación keralty - EPS'!A:A,1,0) -> X600 | Q2: =VLOOKUP(B2,'Consolidado Paramétrica'!C:C,1,0) -> #N/A
B3: X601 | C3: ENVENENAMIENTO AUTOINFLIGIDO INTENCIONALMENTE POR, Y EXPOSICION A ANALGESICOS NO NARCOTICOS, ANTIPIRETICOS Y ANTIRREUMATICOS: INSTITUCION RESIDENCIAL | D3: X60 | E3: ENVENENAMIENTO AUTOINFLINGIDO INTENCIONALMENTE POR, Y EXPOSICION A ANALGESICOS NO NARCOTICOS, ANTIPIRETICOS Y ANTIRREUMATICOS | F3: LESIONES AUTOINFLIGIDAS INTENCIONALMENTE (X60–X84) | G3: 2 | H3: 2 | I3: 22 | J3: Tentativa o intento de suicidio | K3: Ambas | L3: En Programa | M3: APS | N3: 6 meses | O3: LESIONES AUTOINFLINGUIDAS Y SECUELAS | P3: =VLOOKUP(B3,'Validación keralty - EPS'!A:A,1,0) -> X601 | Q3: =VLOOKUP(B3,'Consolidado Paramétrica'!C:C,1,0) -> #N/A
B4: X602 | C4: ENVENENAMIENTO AUTOINFLIGIDO INTENCIONALMENTE POR, Y EXPOSICION A ANALGESICOS NO NARCOTICOS, ANTIPIRETICOS Y ANTIRREUMATICOS: ESCUELAS, OTRAS INSTITUCIONES Y AREAS ADMINISTRATIVAS PUBLICAS | D4: X60 | E4: ENVENENAMIENTO AUTOINFLINGIDO INTENCIONALMENTE POR, Y EXPOSICION A ANALGESICOS NO NARCOTICOS, ANTIPIRETICOS Y ANTIRREUMATICOS | F4: LESIONES AUTOINFLIGIDAS INTENCIONALMENTE (X60–X84) | G4: 2 | H4: 2 | I4: 22 | J4: Tentativa o intento de suicidio | K4: Ambas | L4: En Programa | M4: APS | N4: Sin segmentación | O4: LESIONES AUTOINFLINGUIDAS Y SECUELAS | P4: =VLOOKUP(B4,'Validación keralty - EPS'!A:A,1,0) -> X602 | Q4: =VLOOKUP(B4,'Consolidado Paramétrica'!C:C,1,0) -> #N/A
B5: X603 | C5: ENVENENAMIENTO AUTOINFLIGIDO INTENCIONALMENTE POR, Y EXPOSICION A ANALGESICOS NO NARCOTICOS, ANTIPIRETICOS Y ANTIRREUMATICOS: AREAS DE DEPORTE Y ATLETISMO | D5: X60 | E5: ENVENENAMIENTO AUTOINFLINGIDO INTENCIONALMENTE POR, Y EXPOSICION A ANALGESICOS NO NARCOTICOS, ANTIPIRETICOS Y ANTIRREUMATICOS | F5: LESIONES AUTOINFLIGIDAS INTENCIONALMENTE (X60–X84) | G5: 2 | H5: 2 | I5: 22 | J5: Tentativa o intento de suicidio | K5: Ambas | L5: En Programa | M5: APS | N5: Sin segmentación | O5: LESIONES AUTOINFLINGUIDAS Y SECUELAS | P5: =VLOOKUP(B5,'Validación keralty - EPS'!A:A,1,0) -> X603 | Q5: =VLOOKUP(B5,'Consolidado Paramétrica'!C:C,1,0) -> #N/A
B6: X604 | C6: ENVENENAMIENTO AUTOINFLIGIDO INTENCIONALMENTE POR, Y EXPOSICION A ANALGESICOS NO NARCOTICOS, ANTIPIRETICOS Y ANTIRREUMATICOS: CALLES Y CARRETERAS | D6: X60 | E6: ENVENENAMIENTO AUTOINFLINGIDO INTENCIONALMENTE POR, Y EXPOSICION A ANALGESICOS NO NARCOTICOS, ANTIPIRETICOS Y ANTIRREUMATICOS | F6: LESIONES AUTOINFLIGIDAS INTENCIONALMENTE (X60–X84) | G6: 2 | H6: 2 | I6: 22 | J6: Tentativa o intento de suicidio | K6: Ambas | L6: En Programa | M6: APS | N6: 6 meses | O6: LESIONES AUTOINFLINGUIDAS Y SECUELAS | P6: =VLOOKUP(B6,'Validación keralty - EPS'!A:A,1,0) -> X604 | Q6: =VLOOKUP(B6,'Consolidado Paramétrica'!C:C,1,0) -> #N/A
B7: X605 | C7: ENVENENAMIENTO AUTOINFLIGIDO INTENCIONALMENTE POR, Y EXPOSICION A ANALGESICOS NO NARCOTICOS, ANTIPIRETICOS Y ANTIRREUMATICOS: COMERCIO Y AREAS DE SERVICIO | D7: X60 | E7: ENVENENAMIENTO AUTOINFLINGIDO INTENCIONALMENTE POR, Y EXPOSICION A ANALGESICOS NO NARCOTICOS, ANTIPIRETICOS Y ANTIRREUMATICOS | F7: LESIONES AUTOINFLIGIDAS INTENCIONALMENTE (X60–X84) | G7: 2 | H7: 2 | I7: 22 | J7: Tentativa o intento de suicidio | K7: Ambas | L7: En Programa | M7: APS | N7: Sin segmentación | O7: LESIONES AUTOINFLINGUIDAS Y SECUELAS | P7: =VLOOKUP(B7,'Validación keralty - EPS'!A:A,1,0) -> X605 | Q7: =VLOOKUP(B7,'Consolidado Paramétrica'!C:C,1,0) -> #N/A
B8: X606 | C8: ENVENENAMIENTO AUTOINFLIGIDO INTENCIONALMENTE POR, Y EXPOSICION A ANALGESICOS NO NARCOTICOS, ANTIPIRETICOS Y ANTIRREUMATICOS: AREA INDUSTRIAL Y DE LA CONSTRUCCION | D8: X60 | E8: ENVENENAMIENTO AUTOINFLINGIDO INTENCIONALMENTE POR, Y EXPOSICION A ANALGESICOS NO NARCOTICOS, ANTIPIRETICOS Y ANTIRREUMATICOS | F8: LESIONES AUTOINFLIGIDAS INTENCIONALMENTE (X60–X84) | G8: 2 | H8: 2 | I8: 22 | J8: Tentativa o intento de suicidio | K8: Ambas | L8: En Programa | M8: APS | N8: 6 meses | O8: LESIONES AUTOINFLINGUIDAS Y SECUELAS | P8: =VLOOKUP(B8,'Validación keralty - EPS'!A:A,1,0) -> X606 | Q8: =VLOOKUP(B8,'Consolidado Paramétrica'!C:C,1,0) -> #N/A
B9: X607 | C9: ENVENENAMIENTO AUTOINFLIGIDO INTENCIONALMENTE POR, Y EXPOSICION A ANALGESICOS NO NARCOTICOS, ANTIPIRETICOS Y ANTIRREUMATICOS: GRANJA | D9: X60 | E9: ENVENENAMIENTO AUTOINFLINGIDO INTENCIONALMENTE POR, Y EXPOSICION A ANALGESICOS NO NARCOTICOS, ANTIPIRETICOS Y ANTIRREUMATICOS | F9: LESIONES AUTOINFLIGIDAS INTENCIONALMENTE (X60–X84) | G9: 2 | H9: 2 | I9: 22 | J9: Tentativa o intento de suicidio | K9: Ambas | L9: En Programa | M9: APS | N9: Sin segmentación | O9: LESIONES AUTOINFLINGUIDAS Y SECUELAS | P9: =VLOOKUP(B9,'Validación keralty - EPS'!A:A,1,0) -> X607 | Q9: =VLOOKUP(B9,'Consolidado Paramétrica'!C:C,1,0) -> #N/A
B10: X608 | C10: ENVENENAMIENTO AUTOINFLIGIDO INTENCIONALMENTE POR, Y EXPOSICION A ANALGESICOS NO NARCOTICOS, ANTIPIRETICOS Y ANTIRREUMATICOS: OTRO LUGAR ESPECIFICADO | D10: X60 | E10: ENVENENAMIENTO AUTOINFLINGIDO INTENCIONALMENTE POR, Y EXPOSICION A ANALGESICOS NO NARCOTICOS, ANTIPIRETICOS Y ANTIRREUMATICOS | F10: LESIONES AUTOINFLIGIDAS INTENCIONALMENTE (X60–X84) | G10: 2 | H10: 2 | I10: 22 | J10: Tentativa o intento de suicidio | K10: Ambas | L10: En Programa | M10: APS | N10: Sin segmentación | O10: LESIONES AUTOINFLINGUIDAS Y SECUELAS | P10: =VLOOKUP(B10,'Validación keralty - EPS'!A:A,1,0) -> X608 | Q10: =VLOOKUP(B10,'Consolidado Paramétrica'!C:C,1,0) -> #N/A
B11: X609 | C11: ENVENENAMIENTO AUTOINFLIGIDO INTENCIONALMENTE POR, Y EXPOSICION A ANALGESICOS NO NARCOTICOS, ANTIPIRETICOS Y ANTIRREUMATICOS: LUGAR NO ESPECIFICADO | D11: X60 | E11: ENVENENAMIENTO AUTOINFLINGIDO INTENCIONALMENTE POR, Y EXPOSICION A ANALGESICOS NO NARCOTICOS, ANTIPIRETICOS Y ANTIRREUMATICOS | F11: LESIONES AUTOINFLIGIDAS INTENCIONALMENTE (X60–X84) | G11: 2 | H11: 2 | I11: 22 | J11: Tentativa o intento de suicidio | K11: Ambas | L11: En Programa | M11: APS | N11: 6 meses | O11: LESIONES AUTOINFLINGUIDAS Y SECUELAS | P11: =VLOOKUP(B11,'Validación keralty - EPS'!A:A,1,0) -> X609 | Q11: =VLOOKUP(B11,'Consolidado Paramétrica'!C:C,1,0) -> #N/A
B12: X610 | C12: ENVENENAMIENTO AUTOINFLIGIDO INTENCIONALMENTE POR, Y EXPOSICION A DROGAS ANTIEPILEPTICAS, SEDANTES, HIPNOTICAS, ANTIPARKINSONIANAS Y PSICOTROPICAS, NO CLASIFICADAS EN OTRA PARTE: VIVIENDA | D12: X61 | E12: ENVENENAMIENTO AUTOINFLINGIDO INTENCIONALMENTE POR, Y EXPOSICION A DROGAS ANTIEPILEPTICAS, SEDANTES, HIPNOTICAS, ANTIPARINSONIANAS Y PSICOTROPICAS, NO CLASIFICADAS EN OTRA PARTE | F12: LESIONES AUTOINFLIGIDAS INTENCIONALMENTE (X60–X84) | G12: 2 | H12: 2 | I12: 22 | J12: Tentativa o intento de suicidio | K12: Ambas | L12: En Programa | M12: APS | N12: 6 meses | O12: LESIONES AUTOINFLINGUIDAS Y SECUELAS | P12: =VLOOKUP(B12,'Validación keralty - EPS'!A:A,1,0) -> X610 | Q12: =VLOOKUP(B12,'Consolidado Paramétrica'!C:C,1,0) -> #N/A
B13: X611 | C13: ENVENENAMIENTO AUTOINFLIGIDO INTENCIONALMENTE POR, Y EXPOSICION A DROGAS ANTIEPILEPTICAS, SEDANTES, HIPNOTICAS, ANTIPARKINSONIANAS Y PSICOTROPICAS, NO CLASIFICADAS EN OTRA PARTE: INSTITUCION RESIDENCIAL | D13: X61 | E13: ENVENENAMIENTO AUTOINFLINGIDO INTENCIONALMENTE POR, Y EXPOSICION A DROGAS ANTIEPILEPTICAS, SEDANTES, HIPNOTICAS, ANTIPARINSONIANAS Y PSICOTROPICAS, NO CLASIFICADAS EN OTRA PARTE | F13: LESIONES AUTOINFLIGIDAS INTENCIONALMENTE (X60–X84) | G13: 2 | H13: 2 | I13: 22 | J13: Tentativa o intento de suicidio | K13: Ambas | L13: En Programa | M13: APS | N13: 6 meses | O13: LESIONES AUTOINFLINGUIDAS Y SECUELAS | P13: =VLOOKUP(B13,'Validación keralty - EPS'!A:A,1,0) -> X611 | Q13: =VLOOKUP(B13,'Consolidado Paramétrica'!C:C,1,0) -> #N/A
... B342: Z644 | C342: PROBLEMAS RELACIONADOS CON EL DESACUERDO CON CONSEJEROS | D342: Z64 | E342: PROBLEMAS RELACIONADOS CON CIERTAS CIRCUNSTANCIAS PSICOSOCIALES | F342: PERSONAS CON RIESGOS PARA SU SALUD, POR CIRCUNSTANCIAS SOCIOECONÓMICAS Y PSICOSOCIALES (Z55–Z65) | G342: 2 | H342: 1 | I342: 21 | J342: Problemas psicosociales y de la vida diaria | K342: Adultos | L342: Fuera Programa | M342: APS | N342: 6 meses | O342: PROBLEMAS PSICOSOCIALES | P342: =VLOOKUP(B342,'Validación keralty - EPS'!A:A,1,0) -> Z644 | Q342: =VLOOKUP(B342,'Consolidado Paramétrica'!C:C,1,0) -> #N/A
A343: RETIRO | B343: Z650 | C343: PROBLEMAS RELACIONADOS CON CULPABILIDAD EN PROCEDIMIENTOS CIVILES O CRIMINALES SIN PRISION | D343: Z65 | E343: PROBLEMAS RELACIONADOS CON OTRAS CIRCUNSTANCIAS PSICOSOCIALES | F343: PERSONAS CON RIESGOS PARA SU SALUD, POR CIRCUNSTANCIAS SOCIOECONÓMICAS Y PSICOSOCIALES (Z55–Z65) | G343: 2 | H343: 1 | I343: 21 | J343: Problemas psicosociales y de la vida diaria | K343: Adultos | L343: Fuera Programa | M343: APS | N343: Sin segmentación | O343: NO SE ENCUENTRA EN LA PARAMETRICA DE KERALTY | P343: =VLOOKUP(B343,'Validación keralty - EPS'!A:A,1,0) -> #N/A | Q343: =VLOOKUP(B343,'Consolidado Paramétrica'!C:C,1,0) -> #N/A
B344: Z651 | C344: PROBLEMAS RELACIONADOS CON PRISION Y OTRO ENCARCELAMIENTO | D344: Z65 | E344: PROBLEMAS RELACIONADOS CON OTRAS CIRCUNSTANCIAS PSICOSOCIALES | F344: PERSONAS CON RIESGOS PARA SU SALUD, POR CIRCUNSTANCIAS SOCIOECONÓMICAS Y PSICOSOCIALES (Z55–Z65) | G344: 2 | H344: 1 | I344: 21 | J344: Problemas psicosociales y de la vida diaria | K344: Adultos | L344: Fuera Programa | M344: APS | N344: 6 meses | O344: PROBLEMAS PSICOSOCIALES | P344: =VLOOKUP(B344,'Validación keralty - EPS'!A:A,1,0) -> Z651 | Q344: =VLOOKUP(B344,'Consolidado Paramétrica'!C:C,1,0) -> #N/A
A345: RETIRO | B345: Z652 | C345: PROBLEMAS RELACIONADOS CON LA LIBERACION DE LA PRISION | D345: Z65 | E345: PROBLEMAS RELACIONADOS CON OTRAS CIRCUNSTANCIAS PSICOSOCIALES | F345: PERSONAS CON RIESGOS PARA SU SALUD, POR CIRCUNSTANCIAS SOCIOECONÓMICAS Y PSICOSOCIALES (Z55–Z65) | G345: 2 | H345: 1 | I345: 21 | J345: Problemas psicosociales y de la vida diaria | K345: Adultos | L345: Fuera Programa | M345: APS | N345: Sin segmentación | O345: NO SE ENCUENTRA EN LA PARAMETRICA DE KERALTY | P345: =VLOOKUP(B345,'Validación keralty - EPS'!A:A,1,0) -> #N/A | Q345: =VLOOKUP(B345,'Consolidado Paramétrica'!C:C,1,0) -> #N/A
B346: Z653 | C346: PROBLEMAS RELACIONADOS CON OTRAS CIRCUNSTANCIAS LEGALES | D346: Z65 | E346: PROBLEMAS RELACIONADOS CON OTRAS CIRCUNSTANCIAS PSICOSOCIALES | F346: PERSONAS CON RIESGOS PARA SU SALUD, POR CIRCUNSTANCIAS SOCIOECONÓMICAS Y PSICOSOCIALES (Z55–Z65) | G346: 2 | H346: 1 | I346: 21 | J346: Problemas psicosociales y de la vida diaria | K346: Adultos | L346: Fuera Programa | M346: APS | N346: 6 meses | O346: PROBLEMAS PSICOSOCIALES | P346: =VLOOKUP(B346,'Validación keralty - EPS'!A:A,1,0) -> Z653 | Q346: =VLOOKUP(B346,'Consolidado Paramétrica'!C:C,1,0) -> #N/A
B347: Z654 | C347: PROBLEMAS RELACIONADOS CON VICTIMA DE CRIMEN O TERRORISMO | D347: Z65 | E347: PROBLEMAS RELACIONADOS CON OTRAS CIRCUNSTANCIAS PSICOSOCIALES | F347: PERSONAS CON RIESGOS PARA SU SALUD, POR CIRCUNSTANCIAS SOCIOECONÓMICAS Y PSICOSOCIALES (Z55–Z65) | G347: 2 | H347: 1 | I347: 21 | J347: Problemas psicosociales y de la vida diaria | K347: Adultos | L347: Fuera Programa | M347: APS | N347: 6 meses | O347: PROBLEMAS PSICOSOCIALES | P347: =VLOOKUP(B347,'Validación keralty - EPS'!A:A,1,0) -> Z654 | Q347: =VLOOKUP(B347,'Consolidado Paramétrica'!C:C,1,0) -> #N/A
B348: Z655 | C348: PROBLEMAS RELACIONADOS CON LA EXPOSICION A DESASTRE, GUERRA U OTRAS HOSTILIDADES | D348: Z65 | E348: PROBLEMAS RELACIONADOS CON OTRAS CIRCUNSTANCIAS PSICOSOCIALES | F348: PERSONAS CON RIESGOS PARA SU SALUD, POR CIRCUNSTANCIAS SOCIOECONÓMICAS Y PSICOSOCIALES (Z55–Z65) | G348: 2 | H348: 1 | I348: 21 | J348: Problemas psicosociales y de la vida diaria | K348: Ambas | L348: Fuera Programa | M348: APS | N348: 6 meses | O348: PROBLEMAS PSICOSOCIALES | P348: =VLOOKUP(B348,'Validación keralty - EPS'!A:A,1,0) -> Z655 | Q348: =VLOOKUP(B348,'Consolidado Paramétrica'!C:C,1,0) -> #N/A
B349: Z658 | C349: OTROS PROBLEMAS ESPECIFICADOS RELACIONADOS CON CIRCUNSTANCIAS PSICOSOCIALES | D349: Z65 | E349: PROBLEMAS RELACIONADOS CON OTRAS CIRCUNSTANCIAS PSICOSOCIALES | F349: PERSONAS CON RIESGOS PARA SU SALUD, POR CIRCUNSTANCIAS SOCIOECONÓMICAS Y PSICOSOCIALES (Z55–Z65) | G349: 2 | H349: 1 | I349: 21 | J349: Problemas psicosociales y de la vida diaria | K349: Ambas | L349: Fuera Programa | M349: APS | N349: 6 meses | O349: PROBLEMAS PSICOSOCIALES | P349: =VLOOKUP(B349,'Validación keralty - EPS'!A:A,1,0) -> Z658 | Q349: =VLOOKUP(B349,'Consolidado Paramétrica'!C:C,1,0) -> #N/A
B350: Z659 | C350: PROBLEMAS RELACIONADOS CON CIRCUNSTANCIAS PSICOSOCIALES NO ESPECIFICADAS | D350: Z65 | E350: PROBLEMAS RELACIONADOS CON OTRAS CIRCUNSTANCIAS PSICOSOCIALES | F350: PERSONAS CON RIESGOS PARA SU SALUD, POR CIRCUNSTANCIAS SOCIOECONÓMICAS Y PSICOSOCIALES (Z55–Z65) | G350: 2 | H350: 1 | I350: 21 | J350: Problemas psicosociales y de la vida diaria | K350: Ambas | L350: Fuera Programa | M350: APS | N350: 6 meses | O350: PROBLEMAS PSICOSOCIALES | P350: =VLOOKUP(B350,'Validación keralty - EPS'!A:A,1,0) -> Z659 | Q350: =VLOOKUP(B350,'Consolidado Paramétrica'!C:C,1,0) -> #N/A
B351: Z55 | C351: PROBLEMAS RELACIONADOS CON LA EDUCACION Y LA ALFABETIZACION | D351: Z55 | E351: PROBLEMAS RELACIONADOS CON LA EDUCACION Y LA ALFABETIZACION | F351: PERSONAS CON RIESGOS PARA SU SALUD, POR CIRCUNSTANCIAS SOCIOECONÓMICAS Y PSICOSOCIALES (Z55–Z65) | G351: 2 | H351: 1 | I351: 21 | J351: Problemas psicosociales y de la vida diaria | K351: Niños | L351: Fuera Programa | M351: APS | N351: Sin segmentación | O351: NO SE ENCUENTRA EN LA PARAMETRICA DE KERALTY | P351: =VLOOKUP(B351,'Validación keralty - EPS'!A:A,1,0) -> #N/A | Q351: =VLOOKUP(B351,'Consolidado Paramétrica'!C:C,1,0) -> Z55
B352: Z56 | C352: PROBLEMAS RELACIONADOS CON EL EMPLEO Y EL DESEMPLEO | D352: Z56 | E352: PROBLEMAS RELACIONADOS CON EL EMPLEO Y EL DESEMPLEO | F352: PERSONAS CON RIESGOS PARA SU SALUD, POR CIRCUNSTANCIAS SOCIOECONÓMICAS Y PSICOSOCIALES (Z55–Z65) | G352: 2 | H352: 1 | I352: 21 | J352: Problemas psicosociales y de la vida diaria | K352: Adultos | L352: Fuera Programa | M352: APS | N352: Sin segmentación | O352: NO SE ENCUENTRA EN LA PARAMETRICA DE KERALTY | P352: =VLOOKUP(B352,'Validación keralty - EPS'!A:A,1,0) -> #N/A | Q352: =VLOOKUP(B352,'Consolidado Paramétrica'!C:C,1,0) -> Z56
B353: Z59 | C353: PROBLEMAS RELACIONADOS CON LA VIVIENDA Y LAS CIRCUNSTANCIAS ECONOMICAS | D353: Z59 | E353: PROBLEMAS RELACIONADOS CON LA VIVIENDA Y LAS CIRCUNSTANCIAS ECONOMICAS | F353: PERSONAS CON RIESGOS PARA SU SALUD, POR CIRCUNSTANCIAS SOCIOECONÓMICAS Y PSICOSOCIALES (Z55–Z65) | G353: 2 | H353: 1 | I353: 21 | J353: Problemas psicosociales y de la vida diaria | K353: Adultos | L353: Fuera Programa | M353: APS | N353: Sin segmentación | O353: NO SE ENCUENTRA EN LA PARAMETRICA DE KERALTY | P353: =VLOOKUP(B353,'Validación keralty - EPS'!A:A,1,0) -> #N/A | Q353: =VLOOKUP(B353,'Consolidado Paramétrica'!C:C,1,0) -> Z59
B354: Z60 | C354: PROBLEMAS RELACIONADOS CON EL AMBIENTE SOCIAL | D354: Z60 | E354: PROBLEMAS RELACIONADOS CON EL AMBIENTE SOCIAL | F354: PERSONAS CON RIESGOS PARA SU SALUD, POR CIRCUNSTANCIAS SOCIOECONÓMICAS Y PSICOSOCIALES (Z55–Z65) | G354: 2 | H354: 1 | I354: 21 | J354: Problemas psicosociales y de la vida diaria | K354: Adultos | L354: Fuera Programa | M354: APS | N354: Sin segmentación | O354: NO SE ENCUENTRA EN LA PARAMETRICA DE KERALTY | P354: =VLOOKUP(B354,'Validación keralty - EPS'!A:A,1,0) -> #N/A | Q354: =VLOOKUP(B354,'Consolidado Paramétrica'!C:C,1,0) -> Z60
B355: Z61 | C355: PROBLEMAS RELACIONADOS CON HECHOS NEGATIVOS EN LA NINEZ | D355: Z61 | E355: PROBLEMAS RELACIONADOS CON HECHOS NEGATIVOS EN LA NINEZ | F355: PERSONAS CON RIESGOS PARA SU SALUD, POR CIRCUNSTANCIAS SOCIOECONÓMICAS Y PSICOSOCIALES (Z55–Z65) | G355: 2 | H355: 1 | I355: 21 | J355: Problemas psicosociales y de la vida diaria | K355: Niños | L355: Fuera Programa | M355: APS | N355: Sin segmentación | O355: NO SE ENCUENTRA EN LA PARAMETRICA DE KERALTY | P355: =VLOOKUP(B355,'Validación keralty - EPS'!A:A,1,0) -> #N/A | Q355: =VLOOKUP(B355,'Consolidado Paramétrica'!C:C,1,0) -> Z61
B356: Z62 | C356: OTROS PROBLEMAS RELACIONADOS CON LA CRIANZA DEL NINO | D356: Z62 | E356: OTROS PROBLEMAS RELACIONADOS CON LA CRIANZA DEL NINO | F356: PERSONAS CON RIESGOS PARA SU SALUD, POR CIRCUNSTANCIAS SOCIOECONÓMICAS Y PSICOSOCIALES (Z55–Z65) | G356: 2 | H356: 1 | I356: 21 | J356: Problemas psicosociales y de la vida diaria | K356: Niños | L356: Fuera Programa | M356: APS | N356: Sin segmentación | O356: NO SE ENCUENTRA EN LA PARAMETRICA DE KERALTY | P356: =VLOOKUP(B356,'Validación keralty - EPS'!A:A,1,0) -> #N/A | Q356: =VLOOKUP(B356,'Consolidado Paramétrica'!C:C,1,0) -> Z62
B357: Z63 | C357: PROBLEMAS RELACIONADOS CON EL GRUPO PRIMARIO DE APOYO, INCLUSIVE CIRCUNSTANCIAS FAMILIARES | D357: Z63 | E357: PROBLEMAS RELACIONADOS CON EL GRUPO PRIMARIO DE APOYO, INCLUSIVE CIRCUNSTANCIAS FAMILIARES | F357: PERSONAS CON RIESGOS PARA SU SALUD, POR CIRCUNSTANCIAS SOCIOECONÓMICAS Y PSICOSOCIALES (Z55–Z65) | G357: 2 | H357: 1 | I357: 21 | J357: Problemas psicosociales y de la vida diaria | K357: Adultos | L357: Fuera Programa | M357: APS | N357: 6 meses | O357: PROBLEMAS PSICOSOCIALES | P357: =VLOOKUP(B357,'Validación keralty - EPS'!A:A,1,0) -> Z63 | Q357: =VLOOKUP(B357,'Consolidado Paramétrica'!C:C,1,0) -> Z63
... B372: Z743 | C372: PROBLEMAS RELACIONADOS CON LA NECESIDAD DE SUPERVISION CONTINUA | D372: Z74 | E372: PROBLEMAS RELACIONADOS CON DEPENDENCIA DEL PRESTADOR DE SERVICIOS | F372: PERSONAS EN CONTACTO CON LOS SERVICIOS DE SALUD POR OTRAS CIRCUNSTANCIAS (Z70–Z76) | G372: 2 | H372: 1 | I372: 21 | J372: Problemas psicosociales y de la vida diaria | K372: Adultos | L372: Fuera Programa | M372: APS | N372: 6 meses | O372: PROBLEMAS PSICOSOCIALES | P372: =VLOOKUP(B372,'Validación keralty - EPS'!A:A,1,0) -> Z743 | Q372: =VLOOKUP(B372,'Consolidado Paramétrica'!C:C,1,0) -> #N/A
A373: RETIRO | B373: Z765 | C373: PERSONA QUE CONSULTA CON SIMULACION CONSCIENTE [SIMULADOR] | D373: Z76 | E373: PERSONA EN CONTACTO CON LOS SERVICIOS DE SALUD POR OTRAS CIRCUNSTANCIAS | F373: PERSONAS EN CONTACTO CON LOS SERVICIOS DE SALUD POR OTRAS CIRCUNSTANCIAS (Z70–Z76) | G373: 2 | H373: 1 | I373: 21 | J373: Problemas psicosociales y de la vida diaria | K373: Adultos | L373: Fuera Programa | M373: APS | N373: 6 meses | O373: NO SE ENCUENTRA EN LA PARAMETRICA DE KERALTY | P373: =VLOOKUP(B373,'Validación keralty - EPS'!A:A,1,0) -> #N/A | Q373: =VLOOKUP(B373,'Consolidado Paramétrica'!C:C,1,0) -> #N/A
B374: Z72 | C374: PROBLEMAS RELACIONADOS CON EL ESTILO DE VIDA | D374: Z72 | E374: PROBLEMAS RELACIONADOS CON EL ESTILO DE VIDA | F374: PERSONAS EN CONTACTO CON LOS SERVICIOS DE SALUD POR OTRAS CIRCUNSTANCIAS (Z70–Z76) | G374: 2 | H374: 1 | I374: 21 | J374: Problemas psicosociales y de la vida diaria | K374: Adultos | L374: Fuera Programa | M374: APS | N374: Sin segmentación | O374: NO SE ENCUENTRA EN LA PARAMETRICA DE KERALTY | P374: =VLOOKUP(B374,'Validación keralty - EPS'!A:A,1,0) -> #N/A | Q374: =VLOOKUP(B374,'Consolidado Paramétrica'!C:C,1,0) -> Z72
B375: Z73 | C375: PROBLEMAS RELACIONADOS CON DIFICULTADES CON EL MODO DE VIDA | D375: Z73 | E375: PROBLEMAS RELACIONADOS CON DIFICULTADES CON EL MODO DE VIDA | F375: PERSONAS EN CONTACTO CON LOS SERVICIOS DE SALUD POR OTRAS CIRCUNSTANCIAS (Z70–Z76) | G375: 2 | H375: 1 | I375: 21 | J375: Problemas psicosociales y de la vida diaria | K375: Adultos | L375: Fuera Programa | M375: APS | N375: Sin segmentación | O375: NO SE ENCUENTRA EN LA PARAMETRICA DE KERALTY | P375: =VLOOKUP(B375,'Validación keralty - EPS'!A:A,1,0) -> #N/A | Q375: =VLOOKUP(B375,'Consolidado Paramétrica'!C:C,1,0) -> Z73
B376: Z74 | C376: PROBLEMAS RELACIONADOS CON DEPENDENCIA DEL PRESTADOR DE SERVICIOS | D376: Z74 | E376: PROBLEMAS RELACIONADOS CON DEPENDENCIA DEL PRESTADOR DE SERVICIOS | F376: PERSONAS EN CONTACTO CON LOS SERVICIOS DE SALUD POR OTRAS CIRCUNSTANCIAS (Z70–Z76) | G376: 2 | H376: 1 | I376: 21 | J376: Problemas psicosociales y de la vida diaria | K376: Adultos | L376: Fuera Programa | M376: APS | N376: Sin segmentación | O376: NO SE ENCUENTRA EN LA PARAMETRICA DE KERALTY | P376: =VLOOKUP(B376,'Validación keralty - EPS'!A:A,1,0) -> #N/A | Q376: =VLOOKUP(B376,'Consolidado Paramétrica'!C:C,1,0) -> Z74
A377: RETIRO | B377: Z76 | C377: PERSONA EN CONTACTO CON LOS SERVICIOS DE SALUD POR OTRAS CIRCUNSTANCIAS | D377: Z76 | E377: PERSONA EN CONTACTO CON LOS SERVICIOS DE SALUD POR OTRAS CIRCUNSTANCIAS | F377: PERSONAS EN CONTACTO CON LOS SERVICIOS DE SALUD POR OTRAS CIRCUNSTANCIAS (Z70–Z76) | G377: 2 | H377: 1 | I377: 21 | J377: Problemas psicosociales y de la vida diaria | K377: Adultos | L377: Fuera Programa | M377: APS | N377: Sin segmentación | O377: NO SE ENCUENTRA EN LA PARAMETRICA DE KERALTY | P377: =VLOOKUP(B377,'Validación keralty - EPS'!A:A,1,0) -> #N/A | Q377: =VLOOKUP(B377,'Consolidado Paramétrica'!C:C,1,0) -> #N/A
B378: Z723 | C378: PROBLEMAS RELACIONADOS CON LA FALTA DE EJERCICIO FISICO | D378: Z72 | E378: PROBLEMAS RELACIONADOS CON EL ESTILO DE VIDA | F378: PERSONAS EN CONTACTO CON LOS SERVICIOS DE SALUD POR OTRAS CIRCUNSTANCIAS (Z70–Z76) | G378: 2 | H378: 1 | I378: 21 | J378: Problemas psicosociales y de la vida diaria | K378: Adultos | L378: En Programa | M378: APS | N378: 6 meses | O378: PROBLEMAS PSICOSOCIALES | P378: =VLOOKUP(B378,'Validación keralty - EPS'!A:A,1,0) -> Z723 | Q378: =VLOOKUP(B378,'Consolidado Paramétrica'!C:C,1,0) -> #N/A
B379: Z724 | C379: PROBLEMAS RELACIONADOS CON LA DIETA Y HABITOS ALIMENTARIOS INAPROPIADOS | D379: Z72 | E379: PROBLEMAS RELACIONADOS CON EL ESTILO DE VIDA | F379: PERSONAS EN CONTACTO CON LOS SERVICIOS DE SALUD POR OTRAS CIRCUNSTANCIAS (Z70–Z76) | G379: 2 | H379: 1 | I379: 21 | J379: Problemas psicosociales y de la vida diaria | K379: Adultos | L379: En Programa | M379: APS | N379: 6 meses | O379: PROBLEMAS PSICOSOCIALES | P379: =VLOOKUP(B379,'Validación keralty - EPS'!A:A,1,0) -> Z724 | Q379: =VLOOKUP(B379,'Consolidado Paramétrica'!C:C,1,0) -> #N/A
B380: Z728 | C380: OTROS PROBLEMAS RELACIONADOS CON EL ESTILO DE VIDA | D380: Z72 | E380: PROBLEMAS RELACIONADOS CON EL ESTILO DE VIDA | F380: PERSONAS EN CONTACTO CON LOS SERVICIOS DE SALUD POR OTRAS CIRCUNSTANCIAS (Z70–Z76) | G380: 2 | H380: 1 | I380: 21 | J380: Problemas psicosociales y de la vida diaria | K380: Adultos | L380: En Programa | M380: APS | N380: 6 meses | O380: PROBLEMAS PSICOSOCIALES | P380: =VLOOKUP(B380,'Validación keralty - EPS'!A:A,1,0) -> Z728 | Q380: =VLOOKUP(B380,'Consolidado Paramétrica'!C:C,1,0) -> #N/A
B381: Z729 | C381: PROBLEMA NO ESPECIFICADO RELACIONADO CON EL ESTILO DE VIDA | D381: Z72 | E381: PROBLEMAS RELACIONADOS CON EL ESTILO DE VIDA | F381: PERSONAS EN CONTACTO CON LOS SERVICIOS DE SALUD POR OTRAS CIRCUNSTANCIAS (Z70–Z76) | G381: 2 | H381: 1 | I381: 21 | J381: Problemas psicosociales y de la vida diaria | K381: Adultos | L381: En Programa | M381: APS | N381: 6 meses | O381: PROBLEMAS PSICOSOCIALES | P381: =VLOOKUP(B381,'Validación keralty - EPS'!A:A,1,0) -> Z729 | Q381: =VLOOKUP(B381,'Consolidado Paramétrica'!C:C,1,0) -> #N/A
B382: Z730 | C382: PROBLEMAS RELACIONADOS CON LA ENFERMEDAD CONSUNTIVA | D382: Z73 | E382: PROBLEMAS RELACIONADOS CON DIFICULTADES CON EL MODO DE VIDA | F382: PERSONAS EN CONTACTO CON LOS SERVICIOS DE SALUD POR OTRAS CIRCUNSTANCIAS (Z70–Z76) | G382: 2 | H382: 1 | I382: 21 | J382: Problemas psicosociales y de la vida diaria | K382: Adultos | L382: En Programa | M382: APS | N382: 6 meses | O382: PROBLEMAS PSICOSOCIALES | P382: =VLOOKUP(B382,'Validación keralty - EPS'!A:A,1,0) -> Z730 | Q382: =VLOOKUP(B382,'Consolidado Paramétrica'!C:C,1,0) -> #N/A
...

Sheet Cohorte_Subcohorte
A3: Etiquetas de fila
A4: EPISODIOS DEPRESIVOS Y TRANSTORNOS DEPRESIVOS
A5: EPISODIOS DEPRESIVOS
A6: TRASTORNO DEPRESIVO RECURRENTE
A7: EPISODIOS MANIACOS Y TAB
A8: EPISODIOS MANIACOS
A9: TRASTORNOS AFECTIVO BIPOLAR
A10: ESQUIZOFRENIA Y AFINES
A11: ESQUIZOFRENIA Y AFINES
A12: FACTORES DE RIESGO EN SALUD MENTAL
A13: FACTORES DE RIESGO
A14: LESIONES AUTOINFLINGUIDAS Y SECUELAS
... A73: Total general

Sheet Ponderación
C1: DEMENCIA | D1: TRASTORNO MENTAL ORGANICO | E1: TRASTORNOS MENTALES Y DEL COMPORTAMIENTO DEBIDOS AL USO DE SPA | F1: ESQUIZOFRENIA | G1: TRASTORNO ESQUIZOTIPICO | H1: TRASTORNOS DELIRANTES PERSISTENTES | I1: TRASTORNOS PSICOTICOS AGUDOS Y TRANSITORIOS | J1: TRASTORNO DELIRANTE INDUCIDO | K1: TRASTORNOS ESQUIZOAFECTIVO | L1: OTROS TRASTORNOS PSICOTICOS DE ORIGEN NO ORGANICO | M1: EPISODIO MANIACO | N1: TRASTORNO AFECTIVO BIPOLAR | O1: EPISODIO DEPRESIVO | P1: TRASTORNO DEPRESIVO RECURRENTE | Q1: TRASTORNOS DEL HUMOR [ AFECTIVOS ] PERSISTENTES | R1: OTROS TRASTORNOS DEL HUMOR [ AFECTIVOS ] | S1: TRASTORNOS FOBICOS DE ANSIEDAD | T1: OTROS TRASTORNOS DE ANSIEDAD | U1: TRASTORNO OBSESIVO-COMPULSIVO | V1: REACCION AL ESTRES GRAVE Y TRASTORNOS DE ADAPTACION | W1: TRASTORNOS NEUROTICOS | X1: TRASTORNOS DE LA INGESTION DE ALIMENTOS | Y1: TRASTORNOS NO ORGANICOS DEL SUENO | Z1: DISFUNCION SEXUAL NO OCASIONADA POR TRASTORNOS NI ENFERMEDADES ORGANICOS | AA1: TRASTORNOS MENTALES Y DEL COMPORTAMIENTO ASOCIADOS ALPUERPERIO NO CLASIFICADAS EN OTRA PARTE | AB1: FACTORES PSICOLOGICOS Y DEL COMPORTAMIENTO ASOCIADOS A ENFERMEDADES CLASIFICADOS EN OTRA PARTE | AC1: ABUSO DE SUSTANCIAS QUE NO PRODUCEN DEPENDENCIA | AD1: SINDROME DEL COMPORTAMIENTO ASOCIADOS CON ALTERACIONES FISIOLOGICAS Y FACTORES FISICOS NO ESPECIFICADOS | AE1: TRASTORNOS ESPECIFICOS DE LA PERSONALIDAD | AF1: TRASTORNOS DE LOS HABITOS Y DE LOS IMPULSOS | AG1: TRASTORNOS RELACIONADOS CON LA SEXUALIDAD Y EL GENERO | AH1: OTROS TRASTORNOS DE LA PERSONALIDAD Y DEL COMPORTAMIENTO EN ADULTOS | AI1: RETRASO MENTAL | AJ1: TRASTORNOS ESPECIFICOS DEL DESARROLLO | AK1: TRASTORNOS GENERALIZADOS DEL DESARROLLO | AL1: OTROS TRASTORNOS DEL DESARROLLO PSICOLOGICO | AM1: TRASTORNOS EMOCIONALES Y DEL COMPORTAMIENTO EN NIÑOS Y ADOL | AN1: TRASTORNO MENTAL NO ESPECIFICADO | AO1: PARKINSONISMO SECUNDARIO | AP1: TRASTORNOS DEL SUENO | AQ1: PARALISIS CEREBRAL INFANTIL | AR1: SINTOMAS Y SIGNOS MENTALES | AS1: SINDROMES DEL MALTRATO | AT1: ENVENENAMIENTO Y LESIONES AUTOINFLINGUIDAS | AU1: EVIDENCIA DE ALCOHOLISMO DETERMINADA POR EL NIVEL DE INTOXICACION | AV1: PROBLEMAS PSICOSOCIALES | AW1: HISTORIA FAMILIAR O PERSONAL DE TRASTORNOS MENTALES Y DE COMPORTAMIENTO | AX1: Total
A2: F00-F003 | B2: DEMENCIA | D2: 1 | E2: 1 | F2: 0 | G2: 1 | H2: 0 | I2: 1 | J2: 1 | K2: 0 | L2: 1 | M2: 1 | N2: 0 | O2: 1 | P2: 0 | Q2: 1 | R2: 1 | S2: 1 | T2: 1 | U2: 1 | V2: 1 | W2: 1 | X2: 1 | Y2: 1 | Z2: 1 | AA2: 1 | AB2: 1 | AC2: 1 | AD2: 1 | AE2: 1 | AF2: 1 | AG2: 1 | AH2: 1 | AI2: 1 | AJ2: 1 | AK2: 0 | AL2: 1 | AM2: 1 | AN2: 1 | AO2: 1 | AP2: 1 | AQ2: 0 | AR2: 1 | AS2: 1 | AT2: 1 | AU2: 1 | AV2: 1 | AW2: 1 | AX2: =SUM(C2:AW2) -> 39 | AY2: =AX2/48 -> 0.8125
A3: F04-F09 | B3: TRASTORNO MENTAL ORGANICO | C3: 0 | E3: 0 | F3: 0 | G3: 1 | H3: 0 | I3: 0 | J3: 1 | K3: 0 | L3: 0 | M3: 0 | N3: 0 | O3: 0 | P3: 0 | Q3: 1 | R3: 1 | S3: 1 | T3: 1 | U3: 1 | V3: 1 | W3: 1 | X3: 0 | Y3: 1 | Z3: 1 | AA3: 1 | AB3: 1 | AC3: 1 | AD3: 1 | AE3: 1 | AF3: 1 | AG3: 1 | AH3: 1 | AI3: 0 | AJ3: 1 | AK3: 0 | AL3: 1 | AM3: 1 | AN3: 1 | AO3: 1 | AP3: 1 | AQ3: 0 | AR3: 1 | AS3: 1 | AT3: 1 | AU3: 1 | AV3: 1 | AW3: 1 | AX3: =SUM(C3:AW3) -> 31 | AY3: =AX3/48 -> 0.64583333
A4: F10-F19 | B4: TRASTORNOS MENTALES Y DEL COMPORTAMIENTO DEBIDOS AL USO DE SPA | C4: 0 | D4: 1 | F4: 0 | G4: 1 | H4: 0 | I4: 1 | J4: 1 | K4: 0 | L4: 0 | M4: 1 | N4: 0 | O4: 1 | P4: 0 | Q4: 1 | R4: 1 | S4: 1 | T4: 1 | U4: 1 | V4: 1 | W4: 1 | X4: 0 | Y4: 1 | Z4: 1 | AA4: 1 | AB4: 1 | AC4: 1 | AD4: 1 | AE4: 1 | AF4: 1 | AG4: 1 | AH4: 1 | AI4: 0 | AJ4: 1 | AK4: 0 | AL4: 1 | AM4: 1 | AN4: 1 | AO4: 1 | AP4: 1 | AQ4: 0 | AR4: 1 | AS4: 1 | AT4: 1 | AU4: 1 | AV4: 1 | AW4: 1 | AX4: =SUM(C4:AW4) -> 35 | AY4: =AX4/48 -> 0.72916667
A5: F20 | B5: ESQUIZOFRENIA | C5: 1 | D5: 1 | E5: 1 | G5: 1 | H5: 1 | I5: 1 | J5: 1 | K5: 1 | L5: 1 | M5: 1 | N5: 1 | O5: 1 | P5: 1 | Q5: 1 | R5: 1 | S5: 1 | T5: 1 | U5: 1 | V5: 1 | W5: 1 | X5: 1 | Y5: 1 | Z5: 1 | AA5: 1 | AB5: 1 | AC5: 1 | AD5: 1 | AE5: 1 | AF5: 1 | AG5: 1 | AH5: 1 | AI5: 0 | AJ5: 1 | AK5: 0 | AL5: 1 | AM5: 1 | AN5: 1 | AO5: 1 | AP5: 1 | AQ5: 0 | AR5: 1 | AS5: 1 | AT5: 1 | AU5: 1 | AV5: 1 | AW5: 1 | AX5: =SUM(C5:AW5) -> 43 | AY5: =AX5/48 -> 0.89583333
A6: F21 | B6: TRASTORNO ESQUIZOTIPICO | C6: 0 | D6: 0 | E6: 0 | F6: 0 | H6: 0 | I6: 1 | J6: 1 | K6: 0 | L6: 1 | M6: 1 | N6: 0 | O6: 1 | P6: 0 | Q6: 1 | R6: 1 | S6: 1 | T6: 1 | U6: 1 | V6: 1 | W6: 1 | X6: 1 | Y6: 1 | Z6: 1 | AA6: 1 | AB6: 1 | AC6: 1 | AD6: 1 | AE6: 1 | AF6: 1 | AG6: 1 | AH6: 1 | AI6: 0 | AJ6: 1 | AK6: 0 | AL6: 1 | AM6: 1 | AN6: 1 | AO6: 1 | AP6: 1 | AQ6: 0 | AR6: 1 | AS6: 1 | AT6: 1 | AU6: 1 | AV6: 1 | AW6: 1 | AX6: =SUM(C6:AW6) -> 35 | AZ6: 34
A7: F22 | B7: TRASTORNOS DELIRANTES PERSISTENTES | C7: 1 | D7: 1 | E7: 1 | F7: 0 | G7: 1 | I7: 1 | J7: 1 | K7: 0 | L7: 1 | M7: 1 | N7: 1 | O7: 1 | P7: 1 | Q7: 1 | R7: 1 | S7: 1 | T7: 1 | U7: 1 | V7: 1 | W7: 1 | X7: 1 | Y7: 1 | Z7: 1 | AA7: 1 | AB7: 1 | AC7: 1 | AD7: 1 | AE7: 1 | AF7: 1 | AG7: 1 | AH7: 1 | AI7: 0 | AJ7: 1 | AK7: 0 | AL7: 1 | AM7: 1 | AN7: 1 | AO7: 1 | AP7: 1 | AQ7: 0 | AR7: 1 | AS7: 1 | AT7: 1 | AU7: 1 | AV7: 1 | AW7: 1 | AX7: =SUM(C7:AW7) -> 41
A8: F23 | B8: TRASTORNOS PSICOTICOS AGUDOS Y TRANSITORIOS | C8: 0 | D8: 1 | E8: 0 | F8: 0 | G8: 0 | H8: 0 | J8: 1 | K8: 0 | L8: 0 | M8: 1 | N8: 0 | O8: 1 | P8: 0 | Q8: 0 | R8: 0 | S8: 0 | T8: 0 | U8: 0 | V8: 1 | W8: 1 | X8: 0 | Y8: 1 | Z8: 1 | AA8: 1 | AB8: 1 | AC8: 1 | AD8: 1 | AE8: 0 | AF8: 0 | AG8: 0 | AH8: 0 | AI8: 0 | AJ8: 0 | AK8: 0 | AL8: 1 | AM8: 1 | AN8: 1 | AO8: 1 | AP8: 1 | AQ8: 0 | AR8: 1 | AS8: 1 | AT8: 1 | AU8: 1 | AV8: 1 | AW8: 1 | AX8: =SUM(C8:AW8) -> 23
A9: F24 | B9: TRASTORNO DELIRANTE INDUCIDO | C9: 0 | D9: 0 | E9: 0 | F9: 0 | G9: 0 | H9: 0 | I9: 0 | K9: 0 | L9: 0 | M9: 0 | N9: 0 | O9: 0 | P9: 0 | Q9: 0 | R9: 0 | S9: 0 | T9: 0 | U9: 0 | V9: 0 | W9: 0 | X9: 0 | Y9: 0 | Z9: 0 | AA9: 0 | AB9: 0 | AC9: 1 | AD9: 0 | AE9: 0 | AF9: 0 | AG9: 0 | AH9: 0 | AI9: 0 | AJ9: 0 | AK9: 0 | AL9: 0 | AM9: 0 | AN9: 1 | AO9: 1 | AP9: 0 | AQ9: 0 | AR9: 1 | AS9: 1 | AT9: 0 | AU9: 1 | AV9: 1 | AW9: 1 | AX9: =SUM(C9:AW9) -> 8
A10: F25 | B10: TRASTORNOS ESQUIZOAFECTIVO | C10: 1 | D10: 1 | E10: 1 | F10: 0 | G10: 1 | H10: 1 | I10: 1 | J10: 1 | L10: 1 | M10: 1 | N10: 1 | O10: 1 | P10: 1 | Q10: 1 | R10: 1 | S10: 1 | T10: 1 | U10: 1 | V10: 1 | W10: 1 | X10: 1 | Y10: 1 | Z10: 1 | AA10: 1 | AB10: 1 | AC10: 1 | AD10: 1 | AE10: 1 | AF10: 1 | AG10: 1 | AH10: 1 | AI10: 0 | AJ10: 1 | AK10: 0 | AL10: 1 | AM10: 1 | AN10: 1 | AO10: 1 | AP10: 1 | AQ10: 0 | AR10: 1 | AS10: 1 | AT10: 1 | AU10: 1 | AV10: 1 | AW10: 1 | AX10: =SUM(C10:AW10) -> 42
A11: F28-F29 | B11: OTROS TRASTORNOS PSICOTICOS DE ORIGEN NO ORGANICO | C11: 0 | D11: 1 | E11: 1 | F11: 0 | G11: 0 | H11: 0 | I11: 1 | J11: 1 | K11: 0 | M11: 1 | N11: 0 | O11: 1 | P11: 0 | Q11: 1 | R11: 1 | S11: 1 | T11: 1 | U11: 1 | V11: 1 | W11: 1 | X11: 1 | Y11: 1 | Z11: 1 | AA11: 1 | AB11: 1 | AC11: 1 | AD11: 1 | AE11: 1 | AF11: 1 | AG11: 1 | AH11: 1 | AI11: 0 | AJ11: 1 | AK11: 0 | AL11: 1 | AM11: 1 | AN11: 1 | AO11: 1 | AP11: 1 | AQ11: 0 | AR11: 1 | AS11: 1 | AT11: 1 | AU11: 1 | AV11: 1 | AW11: 1 | AX11: =SUM(C11:AW11) -> 36
A12: F30 | B12: EPISODIO MANIACO | C12: 0 | D12: 1 | E12: 0 | F12: 0 | G12: 0 | H12: 0 | I12: 0 | J12: 1 | K12: 0 | L12: 0 | N12: 0 | O12: 1 | P12: 0 | Q12: 1 | R12: 0 | S12: 1 | T12: 1 | U12: 1 | V12: 1 | W12: 1 | X12: 1 | Y12: 1 | Z12: 1 | AA12: 1 | AB12: 1 | AC12: 1 | AD12: 1 | AE12: 1 | AF12: 1 | AG12: 1 | AH12: 1 | AI12: 0 | AJ12: 1 | AK12: 0 | AL12: 1 | AM12: 1 | AN12: 1 | AO12: 1 | AP12: 1 | AQ12: 0 | AR12: 1 | AS12: 1 | AT12: 1 | AU12: 1 | AV12: 1 | AW12: 1 | AX12: =SUM(C12:AW12) -> 32 | AY12: 33
A13: F31 | B13: TRASTORNO AFECTIVO BIPOLAR | C13: 1 | D13: 1 | E13: 1 | F13: 0 | G13: 1 | H13: 0 | I13: 1 | J13: 1 | K13: 0 | L13: 1 | M13: 1 | O13: 1 | P13: 1 | Q13: 1 | R13: 1 | S13: 1 | T13: 1 | U13: 1 | V13: 1 | W13: 1 | X13: 1 | Y13: 1 | Z13: 1 | AA13: 1 | AB13: 1 | AC13: 1 | AD13: 1 | AE13: 1 | AF13: 1 | AG13: 1 | AH13: 1 | AI13: 0 | AJ13: 1 | AK13: 0 | AL13: 1 | AM13: 1 | AN13: 1 | AO13: 1 | AP13: 1 | AQ13: 0 | AR13: 1 | AS13: 1 | AT13: 1 | AU13: 1 | AV13: 1 | AW13: 1 | AX13: =SUM(C13:AW13) -> 40 | AY13: 41
A14: F32 | B14: EPISODIO DEPRESIVO | C14: 0 | D14: 1 | E14: 0 | F14: 0 | G14: 0 | H14: 0 | I14: 0 | J14: 1 | K14: 0 | L14: 0 | M14: 0 | N14: 0 | P14: 0 | Q14: 1 | R14: 0 | S14: 1 | T14: 1 | U14: 1 | V14: 1 | W14: 1 | X14: 1 | Y14: 1 | Z14: 1 | AA14: 1 | AB14: 1 | AC14: 1 | AD14: 1 | AE14: 1 | AF14: 1 | AG14: 1 | AH14: 1 | AI14: 1 | AJ14: 1 | AK14: 0 | AL14: 1 | AM14: 1 | AN14: 1 | AO14: 1 | AP14: 1 | AQ14: 0 | AR14: 1 | AS14: 1 | AT14: 1 | AU14: 1 | AV14: 1 | AW14: 1 | AX14: =SUM(C14:AW14) -> 32
A15: F33 | B15: TRASTORNO DEPRESIVO RECURRENTE | C15: 1 | D15: 1 | E15: 1 | F15: 0 | G15: 1 | H15: 0 | I15: 1 | J15: 1 | K15: 0 | L15: 1 | M15: 1 | N15: 0 | O15: 1 | Q15: 1 | R15: 1 | S15: 1 | T15: 1 | U15: 1 | V15: 1 | W15: 1 | X15: 1 | Y15: 1 | Z15: 1 | AA15: 1 | AB15: 1 | AC15: 1 | AD15: 1 | AE15: 1 | AF15: 1 | AG15: 1 | AH15: 1 | AI15: 1 | AJ15: 1 | AK15: 0 | AL15: 1 | AM15: 1 | AN15: 1 | AO15: 1 | AP15: 1 | AQ15: 0 | AR15: 1 | AS15: 1 | AT15: 1 | AU15: 1 | AV15: 1 | AW15: 1 | AX15: =SUM(C15:AW15) -> 40
A16: F34 | B16: TRASTORNOS DEL HUMOR [ AFECTIVOS ] PERSISTENTES | C16: 0 | D16: 0 | E16: 0 | F16: 0 | G16: 0 | H16: 0 | I16: 1 | J16: 1 | K16: 0 | L16: 0 | M16: 0 | N16: 0 | O16: 0 | P16: 0 | R16: 0 | S16: 0 | T16: 0 | U16: 0 | V16: 0 | W16: 0 | X16: 0 | Y16: 0 | Z16: 0 | AA16: 0 | AB16: 0 | AC16: 1 | AD16: 0 | AE16: 0 | AF16: 0 | AG16: 0 | AH16: 0 | AI16: 0 | AJ16: 0 | AK16: 0 | AL16: 0 | AM16: 0 | AN16: 1 | AO16: 1 | AP16: 0 | AQ16: 0 | AR16: 1 | AS16: 1 | AT16: 1 | AU16: 1 | AV16: 1 | AW16: 1 | AX16: =SUM(C16:AW16) -> 11
A17: F38-F39 | B17: OTROS TRASTORNOS DEL HUMOR [ AFECTIVOS ] | C17: 0 | D17: 0 | E17: 0 | F17: 0 | G17: 0 | H17: 0 | I17: 1 | J17: 1 | K17: 0 | L17: 0 | M17: 0 | N17: 0 | O17: 1 | P17: 0 | Q17: 1 | S17: 0 | T17: 0 | U17: 0 | V17: 0 | W17: 0 | X17: 0 | Y17: 1 | Z17: 1 | AA17: 1 | AB17: 1 | AC17: 1 | AD17: 1 | AE17: 1 | AF17: 1 | AG17: 1 | AH17: 1 | AI17: 1 | AJ17: 1 | AK17: 0 | AL17: 1 | AM17: 1 | AN17: 1 | AO17: 1 | AP17: 1 | AQ17: 0 | AR17: 1 | AS17: 1 | AT17: 1 | AU17: 1 | AV17: 1 | AW17: 1 | AX17: =SUM(C17:AW17) -> 27
A18: F40 | B18: TRASTORNOS FOBICOS DE ANSIEDAD | C18: 0 | D18: 0 | E18: 0 | F18: 0 | G18: 0 | H18: 0 | I18: 1 | J18: 1 | K18: 0 | L18: 0 | M18: 0 | N18: 0 | O18: 0 | P18: 0 | Q18: 1 | R18: 0 | T18: 1 | U18: 0 | V18: 0 | W18: 0 | X18: 0 | Y18: 1 | Z18: 1 | AA18: 1 | AB18: 1 | AC18: 1 | AD18: 1 | AE18: 0 | AF18: 0 | AG18: 0 | AH18: 0 | AI18: 0 | AJ18: 1 | AK18: 0 | AL18: 1 | AM18: 1 | AN18: 1 | AO18: 1 | AP18: 1 | AQ18: 0 | AR18: 1 | AS18: 1 | AT18: 1 | AU18: 1 | AV18: 1 | AW18: 1 | AX18: =SUM(C18:AW18) -> 22
A19: F41 | B19: OTROS TRASTORNOS DE ANSIEDAD | C19: 0 | D19: 0 | E19: 0 | F19: 0 | G19: 0 | H19: 0 | I19: 1 | J19: 1 | K19: 0 | L19: 0 | M19: 0 | N19: 0 | O19: 0 | P19: 0 | Q19: 1 | R19: 0 | S19: 0 | U19: 0 | V19: 0 | W19: 0 | X19: 0 | Y19: 1 | Z19: 1 | AA19: 1 | AB19: 1 | AC19: 1 | AD19: 1 | AE19: 0 | AF19: 0 | AG19: 0 | AH19: 0 | AI19: 0 | AJ19: 1 | AK19: 0 | AL19: 1 | AM19: 1 | AN19: 1 | AO19: 1 | AP19: 1 | AQ19: 0 | AR19: 1 | AS19: 1 | AT19: 1 | AU19: 1 | AV19: 1 | AW19: 1 | AX19: =SUM(C19:AW19) -> 21
A20: F42 | B20: TRASTORNO OBSESIVO-COMPULSIVO | C20: 0 | D20: 0 | E20: 0 | F20: 0 | G20: 0 | H20: 0 | I20: 1 | J20: 1 | K20: 0 | L20: 0 | M20: 0 | N20: 0 | O20: 0 | P20: 0 | Q20: 1 | R20: 1 | S20: 1 | T20: 1 | V20: 1 | W20: 1 | X20: 0 | Y20: 1 | Z20: 1 | AA20: 1 | AB20: 1 | AC20: 1 | AD20: 1 | AE20: 1 | AF20: 1 | AG20: 1 | AH20: 1 | AI20: 0 | AJ20: 1 | AK20: 0 | AL20: 1 | AM20: 1 | AN20: 1 | AO20: 1 | AP20: 1 | AQ20: 0 | AR20: 1 | AS20: 1 | AT20: 1 | AU20: 1 | AV20: 1 | AW20: 1 | AX20: =SUM(C20:AW20) -> 30
A21: F43 | B21: REACCION AL ESTRES GRAVE Y TRASTORNOS DE ADAPTACION | C21: 0 | D21: 0 | E21: 0 | F21: 0 | G21: 0 | H21: 0 | I21: 1 | J21: 1 | K21: 0 | L21: 0 | M21: 0 | N21: 0 | O21: 0 | P21: 0 | Q21: 1 | R21: 1 | S21: 1 | T21: 1 | U21: 0 | W21: 1 | X21: 0 | Y21: 1 | Z21: 1 | AA21: 1 | AB21: 1 | AC21: 1 | AD21: 1 | AE21: 0 | AF21: 0 | AG21: 0 | AH21: 0 | AI21: 0 | AJ21: 1 | AK21: 0 | AL21: 1 | AM21: 1 | AN21: 1 | AO21: 1 | AP21: 1 | AQ21: 0 | AR21: 1 | AS21: 1 | AT21: 1 | AU21: 1 | AV21: 1 | AW21: 1 | AX21: =SUM(C21:AW21) -> 25
A22: F44-F48 | B22: TRASTORNOS NEUROTICOS | C22: 0 | D22: 0 | E22: 0 | F22: 0 | G22: 0 | H22: 0 | I22: 1 | J22: 1 | K22: 0 | L22: 0 | M22: 0 | N22: 0 | O22: 0 | P22: 0 | Q22: 1 | R22: 1 | S22: 1 | T22: 1 | U22: 0 | V22: 0 | X22: 0 | Y22: 1 | Z22: 1 | AA22: 1 | AB22: 1 | AC22: 1 | AD22: 1 | AE22: 0 | AF22: 0 | AG22: 0 | AH22: 0 | AI22: 0 | AJ22: 1 | AK22: 0 | AL22: 1 | AM22: 1 | AN22: 1 | AO22: 1 | AP22: 1 | AQ22: 0 | AR22: 1 | AS22: 1 | AT22: 1 | AU22: 1 | AV22: 1 | AW22: 1 | AX22: =SUM(C22:AW22) -> 24
A23: F50 | B23: TRASTORNOS DE LA INGESTION DE ALIMENTOS | C23: 0 | D23: 1 | E23: 1 | F23: 0 | G23: 0 | H23: 0 | I23: 1 | J23: 1 | K23: 0 | L23: 0 | M23: 0 | N23: 0 | O23: 0 | P23: 0 | Q23: 1 | R23: 1 | S23: 1 | T23: 1 | U23: 1 | V23: 1 | W23: 1 | Y23: 1 | Z23: 1 | AA23: 1 | AB23: 1 | AC23: 1 | AD23: 1 | AE23: 1 | AF23: 1 | AG23: 1 | AH23: 1 | AI23: 0 | AJ23: 1 | AK23: 0 | AL23: 1 | AM23: 1 | AN23: 1 | AO23: 1 | AP23: 1 | AQ23: 0 | AR23: 1 | AS23: 1 | AT23: 1 | AU23: 1 | AV23: 1 | AW23: 1 | AX23: =SUM(C23:AW23) -> 33
A24: F51 | B24: TRASTORNOS NO ORGANICOS DEL SUENO | C24: 0 | D24: 0 | E24: 0 | F24: 0 | G24: 0 | H24: 0 | I24: 0 | J24: 1 | K24: 0 | L24: 0 | M24: 0 | N24: 0 | O24: 0 | P24: 0 | Q24: 1 | R24: 0 | S24: 0 | T24: 0 | U24: 0 | V24: 0 | W24: 0 | X24: 0 | Z24: 0 | AA24: 1 | AB24: 1 | AC24: 1 | AD24: 1 | AE24: 0 | AF24: 0 | AG24: 0 | AH24: 0 | AI24: 0 | AJ24: 0 | AK24: 0 | AL24: 0 | AM24: 0 | AN24: 1 | AO24: 1 | AP24: 1 | AQ24: 0 | AR24: 1 | AS24: 1 | AT24: 1 | AU24: 1 | AV24: 1 | AW24: 1 | AX24: =SUM(C24:AW24) -> 15
A25: F52 | B25: DISFUNCION SEXUAL NO OCASIONADA POR TRASTORNOS NI ENFERMEDADES ORGANICOS | C25: 0 | D25: 0 | E25: 0 | F25: 0 | G25: 0 | H25: 0 | I25: 0 | J25: 1 | K25: 0 | L25: 0 | M25: 0 | N25: 0 | O25: 0 | P25: 0 | Q25: 1 | R25: 0 | S25: 0 | T25: 0 | U25: 0 | V25: 0 | W25: 0 | X25: 0 | Y25: 1 | AA25: 1 | AB25: 1 | AC25: 1 | AD25: 1 | AE25: 0 | AF25: 0 | AG25: 0 | AH25: 0 | AI25: 0 | AJ25: 0 | AK25: 0 | AL25: 0 | AM25: 0 | AN25: 1 | AO25: 1 | AP25: 1 | AQ25: 0 | AR25: 1 | AS25: 1 | AT25: 1 | AU25: 1 | AV25: 1 | AW25: 1 | AX25: =SUM(C25:AW25) -> 16
A26: F53 | B26: TRASTORNOS MENTALES Y DEL COMPORTAMIENTO ASOCIADOS ALPUERPERIO NO CLASIFICADAS EN OTRA PARTE | C26: 0 | D26: 0 | E26: 0 | F26: 0 | G26: 0 | H26: 0 | I26: 0 | J26: 1 | K26: 0 | L26: 0 | M26: 0 | N26: 0 | O26: 0 | P26: 0 | Q26: 1 | R26: 0 | S26: 0 | T26: 0 | U26: 0 | V26: 0 | W26: 0 | X26: 0 | Y26: 1 | Z26: 0 | AB26: 0 | AC26: 1 | AD26: 0 | AE26: 0 | AF26: 0 | AG26: 0 | AH26: 0 | AI26: 0 | AJ26: 0 | AK26: 0 | AL26: 0 | AM26: 0 | AN26: 1 | AO26: 1 | AP26: 0 | AQ26: 0 | AR26: 1 | AS26: 1 | AT26: 1 | AU26: 1 | AV26: 1 | AW26: 1 | AX26: =SUM(C26:AW26) -> 12
A27: F54 | B27: FACTORES PSICOLOGICOS Y DEL COMPORTAMIENTO ASOCIADOS A ENFERMEDADES CLASIFICADOS EN OTRA PARTE | C27: 0 | D27: 0 | E27: 0 | F27: 0 | G27: 0 | H27: 0 | I27: 0 | J27: 1 | K27: 0 | L27: 0 | M27: 0 | N27: 0 | O27: 0 | P27: 0 | Q27: 1 | R27: 0 | S27: 0 | T27: 0 | U27: 0 | V27: 0 | W27: 0 | X27: 0 | Y27: 1 | Z27: 0 | AA27: 1 | AC27: 1 | AD27: 1 | AE27: 0 | AF27: 0 | AG27: 0 | AH27: 0 | AI27: 0 | AJ27: 0 | AK27: 0 | AL27: 0 | AM27: 0 | AN27: 1 | AO27: 1 | AP27: 0 | AQ27: 0 | AR27: 1 | AS27: 0 | AT27: 0 | AU27: 1 | AV27: 1 | AW27: 1 | AX27: =SUM(C27:AW27) -> 12
A28: F55 | B28: ABUSO DE SUSTANCIAS QUE NO PRODUCEN DEPENDENCIA | C28: 0 | D28: 0 | E28: 0 | F28: 0 | G28: 0 | H28: 0 | I28: 0 | J28: 0 | K28: 0 | L28: 0 | M28: 0 | N28: 0 | O28: 0 | P28: 0 | Q28: 0 | R28: 0 | S28: 0 | T28: 0 | U28: 0 | V28: 0 | W28: 0 | X28: 0 | Y28: 0 | Z28: 0 | AA28: 0 | AB28: 0 | AD28: 0 | AE28: 0 | AF28: 0 | AG28: 0 | AH28: 0 | AI28: 0 | AJ28: 0 | AK28: 0 | AL28: 0 | AM28: 0 | AN28: 1 | AO28: 1 | AP28: 0 | AQ28: 0 | AR28: 1 | AS28: 0 | AT28: 0 | AU28: 1 | AV28: 1 | AW28: 1 | AX28: =SUM(C28:AW28) -> 6
A29: F59 | B29: SINDROME DEL COMPORTAMIENTO ASOCIADOS CON ALTERACIONES FISIOLOGICAS Y FACTORES FISICOS NO ESPECIFICADOS | C29: 0 | D29: 0 | E29: 0 | F29: 0 | G29: 0 | H29: 0 | I29: 0 | J29: 1 | K29: 0 | L29: 0 | M29: 0 | N29: 0 | O29: 0 | P29: 0 | Q29: 1 | R29: 0 | S29: 0 | T29: 0 | U29: 0 | V29: 0 | W29: 0 | X29: 0 | Y29: 1 | Z29: 0 | AA29: 1 | AB29: 0 | AC29: 1 | AE29: 0 | AF29: 0 | AG29: 0 | AH29: 0 | AI29: 0 | AJ29: 0 | AK29: 0 | AL29: 0 | AM29: 0 | AN29: 1 | AO29: 1 | AP29: 0 | AQ29: 0 | AR29: 1 | AS29: 0 | AT29: 0 | AU29: 1 | AV29: 1 | AW29: 1 | AX29: =SUM(C29:AW29) -> 11
A30: F60-F62 | B30: TRASTORNOS ESPECIFICOS DE LA PERSONALIDAD | C30: 0 | D30: 0 | E30: 0 | F30: 0 | G30: 0 | H30: 0 | I30: 1 | J30: 1 | K30: 0 | L30: 0 | M30: 0 | N30: 0 | O30: 0 | P30: 0 | Q30: 1 | R30: 0 | S30: 1 | T30: 1 | U30: 0 | V30: 1 | W30: 1 | X30: 0 | Y30: 1 | Z30: 1 | AA30: 1 | AB30: 1 | AC30: 1 | AD30: 1 | AF30: 1 | AG30: 1 | AH30: 1 | AI30: 0 | AJ30: 0 | AK30: 0 | AL30: 0 | AM30: 0 | AN30: 1 | AO30: 1 | AP30: 1 | AQ30: 0 | AR30: 1 | AS30: 1 | AT30: 1 | AU30: 1 | AV30: 1 | AW30: 1 | AX30: =SUM(C30:AW30) -> 25
A31: F63 | B31: TRASTORNOS DE LOS HABITOS Y DE LOS IMPULSOS | C31: 0 | D31: 0 | E31: 0 | F31: 0 | G31: 0 | H31: 0 | I31: 1 | J31: 1 | K31: 0 | L31: 0 | M31: 0 | N31: 0 | O31: 0 | P31: 0 | Q31: 1 | R31: 0 | S31: 1 | T31: 1 | U31: 0 | V31: 1 | W31: 1 | X31: 0 | Y31: 1 | Z31: 1 | AA31: 1 | AB31: 1 | AC31: 1 | AD31: 1 | AE31: 0 | AG31: 1 | AH31: 1 | AI31: 0 | AJ31: 0 | AK31: 0 | AL31: 0 | AM31: 0 | AN31: 1 | AO31: 1 | AP31: 1 | AQ31: 0 | AR31: 1 | AS31: 1 | AT31: 1 | AU31: 1 | AV31: 1 | AW31: 1 | AX31: =SUM(C31:AW31) -> 24
A32: F64-F66 | B32: TRASTORNOS RELACIONADOS CON LA SEXUALIDAD Y EL GENERO | C32: 0 | D32: 0 | E32: 0 | F32: 0 | G32: 0 | H32: 0 | I32: 1 | J32: 1 | K32: 0 | L32: 0 | M32: 0 | N32: 0 | O32: 0 | P32: 0 | Q32: 1 | R32: 0 | S32: 1 | T32: 1 | U32: 0 | V32: 1 | W32: 1 | X32: 0 | Y32: 1 | Z32: 1 | AA32: 1 | AB32: 1 | AC32: 1 | AD32: 1 | AE32: 0 | AF32: 0 | AH32: 0 | AI32: 0 | AJ32: 0 | AK32: 0 | AL32: 0 | AM32: 0 | AN32: 1 | AO32: 1 | AP32: 1 | AQ32: 0 | AR32: 1 | AS32: 1 | AT32: 1 | AU32: 1 | AV32: 0 | AW32: 0 | AX32: =SUM(C32:AW32) -> 20
A33: F68-F69 | B33: OTROS TRASTORNOS DE LA PERSONALIDAD Y DEL COMPORTAMIENTO EN ADULTOS | C33: 0 | D33: 0 | E33: 0 | F33: 0 | G33: 0 | H33: 0 | I33: 1 | J33: 1 | K33: 0 | L33: 0 | M33: 0 | N33: 0 | O33: 0 | P33: 0 | Q33: 1 | R33: 0 | S33: 1 | T33: 1 | U33: 0 | V33: 1 | W33: 1 | X33: 0 | Y33: 1 | Z33: 1 | AA33: 1 | AB33: 1 | AC33: 1 | AD33: 1 | AE33: 0 | AF33: 0 | AG33: 1 | AI33: 0 | AJ33: 0 | AK33: 0 | AL33: 0 | AM33: 0 | AN33: 1 | AO33: 1 | AP33: 1 | AQ33: 0 | AR33: 1 | AS33: 1 | AT33: 1 | AU33: 1 | AV33: 1 | AW33: 1 | AX33: =SUM(C33:AW33) -> 23
A34: F70-F79 | B34: RETRASO MENTAL | C34: 0 | D34: 1 | E34: 1 | F34: 1 | G34: 1 | H34: 1 | I34: 1 | J34: 1 | K34: 1 | L34: 1 | M34: 1 | N34: 1 | O34: 0 | P34: 0 | Q34: 1 | R34: 0 | S34: 1 | T34: 1 | U34: 1 | V34: 1 | W34: 1 | X34: 1 | Y34: 1 | Z34: 1 | AA34: 1 | AB34: 1 | AC34: 1 | AD34: 1 | AE34: 1 | AF34: 1 | AG34: 1 | AH34: 1 | AJ34: 1 | AK34: 0 | AL34: 1 | AM34: 1 | AN34: 1 | AO34: 1 | AP34: 1 | AQ34: 0 | AR34: 1 | AS34: 1 | AT34: 1 | AU34: 1 | AV34: 1 | AW34: 1 | AX34: =SUM(C34:AW34) -> 40
A35: F80-F83 | B35: TRASTORNOS ESPECIFICOS DEL DESARROLLO | C35: 0 | D35: 0 | E35: 0 | F35: 0 | G35: 0 | H35: 0 | I35: 1 | J35: 1 | K35: 0 | L35: 0 | M35: 0 | N35: 0 | O35: 0 | P35: 0 | Q35: 1 | R35: 0 | S35: 0 | T35: 0 | U35: 0 | V35: 0 | W35: 0 | X35: 0 | Y35: 1 | Z35: 1 | AA35: 1 | AB35: 1 | AC35: 1 | AD35: 1 | AE35: 1 | AF35: 1 | AG35: 1 | AH35: 1 | AI35: 0 | AK35: 0 | AL35: 1 | AM35: 1 | AN35: 1 | AO35: 1 | AP35: 1 | AQ35: 0 | AR35: 1 | AS35: 1 | AT35: 1 | AU35: 1 | AV35: 1 | AW35: 1 | AX35: =SUM(C35:AW35) -> 24
A36: F84 | B36: TRASTORNOS GENERALIZADOS DEL DESARROLLO | C36: 1 | D36: 1 | E36: 1 | F36: 1 | G36: 1 | H36: 1 | I36: 1 | J36: 1 | K36: 1 | L36: 1 | M36: 1 | N36: 1 | O36: 1 | P36: 1 | Q36: 1 | R36: 1 | S36: 1 | T36: 1 | U36: 1 | V36: 1 | W36: 1 | X36: 1 | Y36: 1 | Z36: 1 | AA36: 1 | AB36: 1 | AC36: 1 | AD36: 1 | AE36: 1 | AF36: 1 | AG36: 1 | AH36: 1 | AI36: 1 | AJ36: 1 | AL36: 1 | AM36: 1 | AN36: 1 | AO36: 1 | AP36: 1 | AQ36: 1 | AR36: 1 | AS36: 1 | AT36: 1 | AU36: 1 | AV36: 1 | AW36: 1 | AX36: =SUM(C36:AW36) -> 46
A37: F88-F89 | B37: OTROS TRASTORNOS DEL DESARROLLO PSICOLOGICO | C37: 0 | D37: 0 | E37: 0 | F37: 0 | G37: 0 | H37: 0 | I37: 0 | J37: 1 | K37: 0 | L37: 0 | M37: 0 | N37: 0 | O37: 0 | P37: 0 | Q37: 1 | R37: 0 | S37: 0 | T37: 0 | U37: 0 | V37: 0 | W37: 0 | X37: 0 | Y37: 1 | Z37: 1 | AA37: 1 | AB37: 1 | AC37: 1 | AD37: 1 | AE37: 1 | AF37: 1 | AG37: 1 | AH37: 1 | AI37: 0 | AJ37: 0 | AK37: 0 | AM37: 1 | AN37: 1 | AO37: 1 | AP37: 1 | AQ37: 0 | AR37: 1 | AS37: 1 | AT37: 1 | AU37: 1 | AV37: 1 | AW37: 1 | AX37: =SUM(C37:AW37) -> 22
A38: F90-F98 | B38: TRASTORNOS EMOCIONALES Y DEL COMPORTAMIENTO EN NIÑOS Y ADOL | C38: 0 | D38: 0 | E38: 0 | F38: 0 | G38: 0 | H38: 0 | I38: 0 | J38: 1 | K38: 0 | L38: 0 | M38: 0 | N38: 0 | O38: 0 | P38: 0 | Q38: 1 | R38: 0 | S38: 0 | T38: 0 | U38: 0 | V38: 0 | W38: 0 | X38: 0 | Y38: 1 | Z38: 1 | AA38: 1 | AB38: 1 | AC38: 1 | AD38: 1 | AE38: 1 | AF38: 1 | AG38: 1 | AH38: 1 | AI38: 0 | AJ38: 0 | AK38: 0 | AL38: 0 | AN38: 1 | AO38: 1 | AP38: 1 | AQ38: 0 | AR38: 1 | AS38: 1 | AT38: 1 | AU38: 1 | AV38: 1 | AW38: 1 | AX38: =SUM(C38:AW38) -> 21
A39: F99 | B39: TRASTORNO MENTAL NO ESPECIFICADO | C39: 0 | D39: 0 | E39: 0 | F39: 0 | G39: 0 | H39: 0 | I39: 0 | J39: 0 | K39: 0 | L39: 0 | M39: 0 | N39: 0 | O39: 0 | P39: 0 | Q39: 0 | R39: 0 | S39: 0 | T39: 0 | U39: 0 | V39: 0 | W39: 0 | X39: 0 | Y39: 0 | Z39: 0 | AA39: 0 | AB39: 0 | AC39: 0 | AD39: 0 | AE39: 0 | AF39: 0 | AG39: 0 | AH39: 0 | AI39: 0 | AJ39: 0 | AK39: 0 | AL39: 0 | AM39: 0 | AO39: 1 | AP39: 0 | AQ39: 0 | AR39: 1 | AS39: 0 | AT39: 0 | AU39: 1 | AV39: 1 | AW39: 1 | AX39: =SUM(C39:AW39) -> 5
A40: G21 | B40: PARKINSONISMO SECUNDARIO | C40: 0 | D40: 0 | E40: 0 | F40: 0 | G40: 0 | H40: 0 | I40: 0 | J40: 0 | K40: 0 | L40: 0 | M40: 0 | N40: 0 | O40: 0 | P40: 0 | Q40: 0 | R40: 0 | S40: 0 | T40: 0 | U40: 0 | V40: 0 | W40: 0 | X40: 0 | Y40: 0 | Z40: 0 | AA40: 0 | AB40: 0 | AC40: 0 | AD40: 0 | AE40: 0 | AF40: 0 | AG40: 0 | AH40: 0 | AI40: 0 | AJ40: 0 | AK40: 0 | AL40: 0 | AM40: 0 | AN40: 0 | AP40: 0 | AQ40: 0 | AR40: 1 | AS40: 0 | AT40: 0 | AU40: 1 | AV40: 1 | AW40: 1 | AX40: =SUM(C40:AW40) -> 4
...

Sheet Validación keralty - EPS
